Workbook

Sheet DAILY_STATUS
A1: DAILY STATUS BOARD
A2: Change day (B3). Mark sick/swap in ROSTER first → this updates automatically.
A3: SELECT DAY → | B3: 1 | C3: (1-28)
A4: Day of Week | B4: =CHOOSE(MOD(B3-1,7)+1,"Mon","Tue","Wed","Thu","Fri","Sat","Sun") -> Mon
A6: TODAY'S ASSIGNMENTS
A7: Staff | B7: Team | C7: Skill | D7: Shift | E7: Status | G7: Action Needed
A8: =ROSTER!A4 -> Alice Johnson | B8: =ROSTER!B4 -> Day A | C8: =ROSTER!D4 -> 1 | D8: =IF(OR($B$3<1,$B$3>28),"—",INDEX(ROSTER!E4:AF4,1,$B$3)) -> EL | E8: =IF(D8="SICK","🔴 SICK",IF(D8="AL","🟡 AL",IF(D8="OFF","⬜ OFF",IF(D8="AVL","🔵 FLOAT",IF(OR(D8="AG-E",D8="AG-L",D8="AG-N"),"🟠 AGENCY",IF(OR(D8="OC-E",D8="OC-L",D8="OC-EL",D8="OC-N"),"🟣 ON-CALL","🟢 WORKING")))))) -> 🟢 WORKING | G8: =IF(D8="SICK","⚡ FIND COVER — check Available list below",IF(D8="AVL","Ready to deploy if gap arises",IF(OR(D8="AG-E",D8="AG-L",D8="AG-N"),"Confirm agency arrival. Handover pack ready?","")))
A9: =ROSTER!A5 -> Bob Smith | B9: =ROSTER!B5 -> Day A | C9: =ROSTER!D5 -> 0.5 | D9: =IF(OR($B$3<1,$B$3>28),"—",INDEX(ROSTER!E5:AF5,1,$B$3)) -> EL | E9: =IF(D9="SICK","🔴 SICK",IF(D9="AL","🟡 AL",IF(D9="OFF","⬜ OFF",IF(D9="AVL","🔵 FLOAT",IF(OR(D9="AG-E",D9="AG-L",D9="AG-N"),"🟠 AGENCY",IF(OR(D9="OC-E",D9="OC-L",D9="OC-EL",D9="OC-N"),"🟣 ON-CALL","🟢 WORKING")))))) -> 🟢 WORKING | G9: =IF(D9="SICK","⚡ FIND COVER — check Available list below",IF(D9="AVL","Ready to deploy if gap arises",IF(OR(D9="AG-E",D9="AG-L",D9="AG-N"),"Confirm agency arrival. Handover pack ready?","")))
A10: =ROSTER!A6 -> Carol Davis | B10: =ROSTER!B6 -> Day A | C10: =ROSTER!D6 -> 1 | D10: =IF(OR($B$3<1,$B$3>28),"—",INDEX(ROSTER!E6:AF6,1,$B$3)) -> EL | E10: =IF(D10="SICK","🔴 SICK",IF(D10="AL","🟡 AL",IF(D10="OFF","⬜ OFF",IF(D10="AVL","🔵 FLOAT",IF(OR(D10="AG-E",D10="AG-L",D10="AG-N"),"🟠 AGENCY",IF(OR(D10="OC-E",D10="OC-L",D10="OC-EL",D10="OC-N"),"🟣 ON-CALL","🟢 WORKING")))))) -> 🟢 WORKING | G10: =IF(D10="SICK","⚡ FIND COVER — check Available list below",IF(D10="AVL","Ready to deploy if gap arises",IF(OR(D10="AG-E",D10="AG-L",D10="AG-N"),"Confirm agency arrival. Handover pack ready?","")))
A11: =ROSTER!A7 -> David Wilson | B11: =ROSTER!B7 -> Day A | C11: =ROSTER!D7 -> 0.5 | D11: =IF(OR($B$3<1,$B$3>28),"—",INDEX(ROSTER!E7:AF7,1,$B$3)) -> EL | E11: =IF(D11="SICK","🔴 SICK",IF(D11="AL","🟡 AL",IF(D11="OFF","⬜ OFF",IF(D11="AVL","🔵 FLOAT",IF(OR(D11="AG-E",D11="AG-L",D11="AG-N"),"🟠 AGENCY",IF(OR(D11="OC-E",D11="OC-L",D11="OC-EL",D11="OC-N"),"🟣 ON-CALL","🟢 WORKING")))))) -> 🟢 WORKING | G11: =IF(D11="SICK","⚡ FIND COVER — check Available list below",IF(D11="AVL","Ready to deploy if gap arises",IF(OR(D11="AG-E",D11="AG-L",D11="AG-N"),"Confirm agency arrival. Handover pack ready?","")))
A12: =ROSTER!A8 -> Emma Brown | B12: =ROSTER!B8 -> Day A | C12: =ROSTER!D8 -> 1.5 | D12: =IF(OR($B$3<1,$B$3>28),"—",INDEX(ROSTER!E8:AF8,1,$B$3)) -> EL | E12: =IF(D12="SICK","🔴 SICK",IF(D12="AL","🟡 AL",IF(D12="OFF","⬜ OFF",IF(D12="AVL","🔵 FLOAT",IF(OR(D12="AG-E",D12="AG-L",D12="AG-N"),"🟠 AGENCY",IF(OR(D12="OC-E",D12="OC-L",D12="OC-EL",D12="OC-N"),"🟣 ON-CALL","🟢 WORKING")))))) -> 🟢 WORKING | G12: =IF(D12="SICK","⚡ FIND COVER — check Available list below",IF(D12="AVL","Ready to deploy if gap arises",IF(OR(D12="AG-E",D12="AG-L",D12="AG-N"),"Confirm agency arrival. Handover pack ready?","")))
A13: =ROSTER!A9 -> Fiona Hart | B13: =ROSTER!B9 -> Day A | C13: =ROSTER!D9 -> 0.5 | D13: =IF(OR($B$3<1,$B$3>28),"—",INDEX(ROSTER!E9:AF9,1,$B$3)) -> EL | E13: =IF(D13="SICK","🔴 SICK",IF(D13="AL","🟡 AL",IF(D13="OFF","⬜ OFF",IF(D13="AVL","🔵 FLOAT",IF(OR(D13="AG-E",D13="AG-L",D13="AG-N"),"🟠 AGENCY",IF(OR(D13="OC-E",D13="OC-L",D13="OC-EL",D13="OC-N"),"🟣 ON-CALL","🟢 WORKING")))))) -> 🟢 WORKING | G13: =IF(D13="SICK","⚡ FIND COVER — check Available list below",IF(D13="AVL","Ready to deploy if gap arises",IF(OR(D13="AG-E",D13="AG-L",D13="AG-N"),"Confirm agency arrival. Handover pack ready?","")))
A14: =ROSTER!A10 -> George King | B14: =ROSTER!B10 -> Day A | C14: =ROSTER!D10 -> 1 | D14: =IF(OR($B$3<1,$B$3>28),"—",INDEX(ROSTER!E10:AF10,1,$B$3)) -> EL | E14: =IF(D14="SICK","🔴 SICK",IF(D14="AL","🟡 AL",IF(D14="OFF","⬜ OFF",IF(D14="AVL","🔵 FLOAT",IF(OR(D14="AG-E",D14="AG-L",D14="AG-N"),"🟠 AGENCY",IF(OR(D14="OC-E",D14="OC-L",D14="OC-EL",D14="OC-N"),"🟣 ON-CALL","🟢 WORKING")))))) -> 🟢 WORKING | G14: =IF(D14="SICK","⚡ FIND COVER — check Available list below",IF(D14="AVL","Ready to deploy if gap arises",IF(OR(D14="AG-E",D14="AG-L",D14="AG-N"),"Confirm agency arrival. Handover pack ready?","")))
A15: =ROSTER!A11 -> Hannah Lee | B15: =ROSTER!B11 -> Day B | C15: =ROSTER!D11 -> 1 | D15: =IF(OR($B$3<1,$B$3>28),"—",INDEX(ROSTER!E11:AF11,1,$B$3)) -> OFF | E15: =IF(D15="SICK","🔴 SICK",IF(D15="AL","🟡 AL",IF(D15="OFF","⬜ OFF",IF(D15="AVL","🔵 FLOAT",IF(OR(D15="AG-E",D15="AG-L",D15="AG-N"),"🟠 AGENCY",IF(OR(D15="OC-E",D15="OC-L",D15="OC-EL",D15="OC-N"),"🟣 ON-CALL","🟢 WORKING")))))) -> ⬜ OFF | G15: =IF(D15="SICK","⚡ FIND COVER — check Available list below",IF(D15="AVL","Ready to deploy if gap arises",IF(OR(D15="AG-E",D15="AG-L",D15="AG-N"),"Confirm agency arrival. Handover pack ready?","")))
A16: =ROSTER!A12 -> Ian Clark | B16: =ROSTER!B12 -> Day B | C16: =ROSTER!D12 -> 0.5 | D16: =IF(OR($B$3<1,$B$3>28),"—",INDEX(ROSTER!E12:AF12,1,$B$3)) -> OFF | E16: =IF(D16="SICK","🔴 SICK",IF(D16="AL","🟡 AL",IF(D16="OFF","⬜ OFF",IF(D16="AVL","🔵 FLOAT",IF(OR(D16="AG-E",D16="AG-L",D16="AG-N"),"🟠 AGENCY",IF(OR(D16="OC-E",D16="OC-L",D16="OC-EL",D16="OC-N"),"🟣 ON-CALL","🟢 WORKING")))))) -> ⬜ OFF | G16: =IF(D16="SICK","⚡ FIND COVER — check Available list below",IF(D16="AVL","Ready to deploy if gap arises",IF(OR(D16="AG-E",D16="AG-L",D16="AG-N"),"Confirm agency arrival. Handover pack ready?","")))
A17: =ROSTER!A13 -> Julia Martin | B17: =ROSTER!B13 -> Day B | C17: =ROSTER!D13 -> 1 | D17: =IF(OR($B$3<1,$B$3>28),"—",INDEX(ROSTER!E13:AF13,1,$B$3)) -> OFF | E17: =IF(D17="SICK","🔴 SICK",IF(D17="AL","🟡 AL",IF(D17="OFF","⬜ OFF",IF(D17="AVL","🔵 FLOAT",IF(OR(D17="AG-E",D17="AG-L",D17="AG-N"),"🟠 AGENCY",IF(OR(D17="OC-E",D17="OC-L",D17="OC-EL",D17="OC-N"),"🟣 ON-CALL","🟢 WORKING")))))) -> ⬜ OFF | G17: =IF(D17="SICK","⚡ FIND COVER — check Available list below",IF(D17="AVL","Ready to deploy if gap arises",IF(OR(D17="AG-E",D17="AG-L",D17="AG-N"),"Confirm agency arrival. Handover pack ready?","")))
A18: =ROSTER!A14 -> Kevin White | B18: =ROSTER!B14 -> Day B | C18: =ROSTER!D14 -> 0.5 | D18: =IF(OR($B$3<1,$B$3>28),"—",INDEX(ROSTER!E14:AF14,1,$B$3)) -> OFF | E18: =IF(D18="SICK","🔴 SICK",IF(D18="AL","🟡 AL",IF(D18="OFF","⬜ OFF",IF(D18="AVL","🔵 FLOAT",IF(OR(D18="AG-E",D18="AG-L",D18="AG-N"),"🟠 AGENCY",IF(OR(D18="OC-E",D18="OC-L",D18="OC-EL",D18="OC-N"),"🟣 ON-CALL","🟢 WORKING")))))) -> ⬜ OFF | G18: =IF(D18="SICK","⚡ FIND COVER — check Available list below",IF(D18="AVL","Ready to deploy if gap arises",IF(OR(D18="AG-E",D18="AG-L",D18="AG-N"),"Confirm agency arrival. Handover pack ready?","")))
A19: =ROSTER!A15 -> Laura Adams | B19: =ROSTER!B15 -> Day B | C19: =ROSTER!D15 -> 1.5 | D19: =IF(OR($B$3<1,$B$3>28),"—",INDEX(ROSTER!E15:AF15,1,$B$3)) -> OFF | E19: =IF(D19="SICK","🔴 SICK",IF(D19="AL","🟡 AL",IF(D19="OFF","⬜ OFF",IF(D19="AVL","🔵 FLOAT",IF(OR(D19="AG-E",D19="AG-L",D19="AG-N"),"🟠 AGENCY",IF(OR(D19="OC-E",D19="OC-L",D19="OC-EL",D19="OC-N"),"🟣 ON-CALL","🟢 WORKING")))))) -> ⬜ OFF | G19: =IF(D19="SICK","⚡ FIND COVER — check Available list below",IF(D19="AVL","Ready to deploy if gap arises",IF(OR(D19="AG-E",D19="AG-L",D19="AG-N"),"Confirm agency arrival. Handover pack ready?","")))
... A32: =ROSTER!A28 -> Yasmin Reed | B32: =ROSTER!B28 -> Day B | C32: =ROSTER!D28 -> 1 | D32: =IF(OR($B$3<1,$B$3>28),"—",INDEX(ROSTER!E28:AF28,1,$B$3)) -> OFF | E32: =IF(D32="SICK","🔴 SICK",IF(D32="AL","🟡 AL",IF(D32="OFF","⬜ OFF",IF(D32="AVL","🔵 FLOAT",IF(OR(D32="AG-E",D32="AG-L",D32="AG-N"),"🟠 AGENCY",IF(OR(D32="OC-E",D32="OC-L",D32="OC-EL",D32="OC-N"),"🟣 ON-CALL","🟢 WORKING")))))) -> ⬜ OFF | G32: =IF(D32="SICK","⚡ FIND COVER — check Available list below",IF(D32="AVL","Ready to deploy if gap arises",IF(OR(D32="AG-E",D32="AG-L",D32="AG-N"),"Confirm agency arrival. Handover pack ready?","")))
A33: =ROSTER!A29 -> 0 | C33: =ROSTER!D29 -> 0 | D33: =IF(OR($B$3<1,$B$3>28),"—",INDEX(ROSTER!E29:AF29,1,$B$3)) -> 0
A34: =ROSTER!A30 -> 0 | C34: =ROSTER!D30 -> 0 | D34: =IF(OR($B$3<1,$B$3>28),"—",INDEX(ROSTER!E30:AF30,1,$B$3)) -> 0
A35: =ROSTER!A31 -> 0 | C35: =ROSTER!D31 -> 0 | D35: =IF(OR($B$3<1,$B$3>28),"—",INDEX(ROSTER!E31:AF31,1,$B$3)) -> 0
A36: =ROSTER!A32 -> 0 | C36: =ROSTER!D32 -> 0 | D36: =IF(OR($B$3<1,$B$3>28),"—",INDEX(ROSTER!E32:AF32,1,$B$3)) -> 0
A37: =ROSTER!A33 -> 0 | C37: =ROSTER!D33 -> 0 | D37: =IF(OR($B$3<1,$B$3>28),"—",INDEX(ROSTER!E33:AF33,1,$B$3)) -> 0
A38: =ROSTER!A34 -> 0 | C38: =ROSTER!D34 -> 0 | D38: =IF(OR($B$3<1,$B$3>28),"—",INDEX(ROSTER!E34:AF34,1,$B$3)) -> 0
A39: =ROSTER!A35 -> 0 | C39: =ROSTER!D35 -> 0 | D39: =IF(OR($B$3<1,$B$3>28),"—",INDEX(ROSTER!E35:AF35,1,$B$3)) -> 0
A40: =ROSTER!A36 -> 0 | C40: =ROSTER!D36 -> 0 | D40: =IF(OR($B$3<1,$B$3>28),"—",INDEX(ROSTER!E36:AF36,1,$B$3)) -> 0
A41: =ROSTER!A37 -> 0 | C41: =ROSTER!D37 -> 0 | D41: =IF(OR($B$3<1,$B$3>28),"—",INDEX(ROSTER!E37:AF37,1,$B$3)) -> 0
A42: =ROSTER!A38 -> 0 | C42: =ROSTER!D38 -> 0 | D42: =IF(OR($B$3<1,$B$3>28),"—",INDEX(ROSTER!E38:AF38,1,$B$3)) -> 0
A43: =ROSTER!A39 -> 0 | C43: =ROSTER!D39 -> 0 | D43: =IF(OR($B$3<1,$B$3>28),"—",INDEX(ROSTER!E39:AF39,1,$B$3)) -> 0
A44: =ROSTER!A40 -> 0 | C44: =ROSTER!D40 -> 0 | D44: =IF(OR($B$3<1,$B$3>28),"—",INDEX(ROSTER!E40:AF40,1,$B$3)) -> 0
... A54: =ROSTER!A50 -> 0 | C54: =ROSTER!D50 -> 0 | D54: =IF(OR($B$3<1,$B$3>28),"—",INDEX(ROSTER!E50:AF50,1,$B$3)) -> 0
A57: COVERAGE
A58: Metric | B58: Count | C58: Min | D58: Status
A59: Early | B59: =COUNTIF(D8:D54,"EL")+COUNTIF(D8:D54,"E")+COUNTIF(D8:D54,"OC-E")+COUNTIF(D8:D54,"OC-EL")+COUNTIF(D8:D54,"AG-E")+COUNTIF(D8:D54,"BH-D") -> 8 | C59: 3 | D59: =IF(B59>=C59+3,"🟢 STRONG",IF(B59>=C59+1,"🟡 OK",IF(B59>=C59,"🟠 AT MIN","🔴 BELOW MIN"))) -> 🟢 STRONG
A60: Late | B60: =COUNTIF(D8:D54,"EL")+COUNTIF(D8:D54,"L")+COUNTIF(D8:D54,"OC-L")+COUNTIF(D8:D54,"OC-EL")+COUNTIF(D8:D54,"AG-L")+COUNTIF(D8:D54,"BH-D") -> 7 | C60: 3 | D60: =IF(B60>=C60+3,"🟢 STRONG",IF(B60>=C60+1,"🟡 OK",IF(B60>=C60,"🟠 AT MIN","🔴 BELOW MIN"))) -> 🟢 STRONG
A61: Night | B61: =COUNTIF(D8:D54,"N")+COUNTIF(D8:D54,"OC-N")+COUNTIF(D8:D54,"AG-N")+COUNTIF(D8:D54,"BH-N") -> 3 | C61: 3 | D61: =IF(B61>=C61+3,"🟢 STRONG",IF(B61>=C61+1,"🟡 OK",IF(B61>=C61,"🟠 AT MIN","🔴 BELOW MIN"))) -> 🟠 AT MIN
A62: Sick | B62: =COUNTIF(D8:D54,"SICK") -> 0
A63: AL | B63: =COUNTIF(D8:D54,"AL") -> 0
A64: Float Avail | B64: =COUNTIF(D8:D54,"AVL") -> 3
...

Sheet CONTINGENCY_PLAN
A1: CONTINGENCY & FORTIFICATION PLAN
A3: ESCALATION PROTOCOL
A4: Level | B4: Trigger & Actions | C4: Max Duration
A5: ⬜ LVL 0 | B5: All covered. Float standby. | C5: Indefinite
A6: 🟢 LVL 1 | B6: Float deployed (1-3 gaps). OT alerted. | C6: 7 days
A7: 🟡 LVL 2 | B7: OT activated. Bank staff called. | C7: 7 days WTR
A8: 🟠 LVL 3 | B8: Agency booked. Handover pack ready. | C8: 14 days
A9: 🔴 LVL 4 | B9: Agency unavailable. Manager on floor. Emergency call-in 1.5x. | C9: 48hrs max
A10: ⚫ LVL 5 | B10: Close admissions. Notify CQC. Mutual aid. | C10: Immediate
A13: NIGHT VULNERABILITY COUNTERMEASURES
A14: 1. Night-First Float | B14: Float deploys night BEFORE day. Night=0 buffer; Day=4-5 buffer.
A15: 2. Standing Agency Night | B15: Pre-book 1 agency night/wk Nov-Mar. Cancel 24hrs. £343/wk.
A16: 3. 4th Night Staff | B16: Recruit 1 extra per night team. +£55K/yr. Eliminates #1 vulnerability.
A17: 4. Night Bank Staff | B17: 2 bank workers night-available. Zero-hours. Base+£3. 2hr response.
A18: 5. Mutual Aid Pact | B18: Agreement with 2-3 neighbouring homes to loan night staff at agreed rate.
A21: WEEKLY OT CAP (WTR)
A22: Daily model: OT=4/day. Weekly truth: same 4 people, max 8 shifts/wk.
A24: Scenario | B24: Gaps/d | C24: Gaps/wk | D24: Float/wk | E24: OT/wk | F24: Agency/wk | G24: Ag £/wk
A25: CLEAN | B25: 0 | C25: =B25*7 -> 0 | D25: =MIN(C25,15) -> 0 | E25: =MIN(MAX(C25-D25,0),CONFIG!$B$59) -> 0 | F25: =MAX(C25-D25-E25,0) -> 0 | G25: =(F25*0.7*12.25*CONFIG!$B$29+F25*0.3*12.25*CONFIG!$B$30) -> 0
A26: TYPICAL | B26: 2 | C26: =B26*7 -> 14 | D26: =MIN(C26,15) -> 14 | E26: =MIN(MAX(C26-D26,0),CONFIG!$B$59) -> 0 | F26: =MAX(C26-D26-E26,0) -> 0 | G26: =(F26*0.7*12.25*CONFIG!$B$29+F26*0.3*12.25*CONFIG!$B$30) -> 0
A27: BAD | B27: 4 | C27: =B27*7 -> 28 | D27: =MIN(C27,15) -> 15 | E27: =MIN(MAX(C27-D27,0),CONFIG!$B$59) -> 8 | F27: =MAX(C27-D27-E27,0) -> 5 | G27: =(F27*0.7*12.25*CONFIG!$B$29+F27*0.3*12.25*CONFIG!$B$30) -> 1457.75
A28: CRISIS | B28: 5 | C28: =B28*7 -> 35 | D28: =MIN(C28,15) -> 15 | E28: =MIN(MAX(C28-D28,0),CONFIG!$B$59) -> 8 | F28: =MAX(C28-D28-E28,0) -> 12 | G28: =(F28*0.7*12.25*CONFIG!$B$29+F28*0.3*12.25*CONFIG!$B$30) -> 3498.6
A29: WORST | B29: 6 | C29: =B29*7 -> 42 | D29: =MIN(C29,15) -> 15 | E29: =MIN(MAX(C29-D29,0),CONFIG!$B$59) -> 8 | F29: =MAX(C29-D29-E29,0) -> 19 | G29: =(F29*0.7*12.25*CONFIG!$B$29+F29*0.3*12.25*CONFIG!$B$30) -> 5539.45
A30: PANDEMIC | B30: 8 | C30: =B30*7 -> 56 | D30: =MIN(C30,15) -> 15 | E30: =MIN(MAX(C30-D30,0),CONFIG!$B$59) -> 8 | F30: =MAX(C30-D30-E30,0) -> 33 | G30: =(F30*0.7*12.25*CONFIG!$B$29+F30*0.3*12.25*CONFIG!$B$30) -> 9621.15
A32: BAD WEEK: daily model shows 0 agency. Weekly shows 5 needed.
A35: NOROVIRUS WAVE (14 days)
A37: Day | B37: Sick | C37: Float | D37: OT | E37: Agency | F37: Shortfall | G37: Level | H37: Cost | I37: Actions
A38: 1 | B38: 2 | C38: =MIN(B38,3) -> 2 | D38: =MIN(MAX(B38-C38,0),4) -> 0 | E38: =MAX(B38-C38-D38,0) -> 0 | F38: =MAX(E38-ROUND(E38*CONFIG!$B$60,0),0) -> 0 | G38: =IF(F38>0,"🔴 LVL4-5",IF(E38>0,"🟠 LVL3",IF(D38>0,"🟡 LVL2",IF(C38>0,"🟢 LVL1","⬜ LVL0")))) -> 🟢 LVL1 | H38: =1539+D38*12.25*(CONFIG!$B$28-1)*CONFIG!$B$61+MIN(E38,ROUND(E38*CONFIG!$B$60,0))*0.7*12.25*CONFIG!$B$29+MIN(E38,ROUND(E38*CONFIG!$B$60,0))*0.3*12.25*CONFIG!$B$30+F38*CONFIG!$B$57*12.25 -> 1539 | I38: Index cases
A39: 2 | B39: 4 | C39: =MIN(B39,3) -> 3 | D39: =MIN(MAX(B39-C39,0),4) -> 1 | E39: =MAX(B39-C39-D39,0) -> 0 | F39: =MAX(E39-ROUND(E39*CONFIG!$B$60,0),0) -> 0 | G39: =IF(F39>0,"🔴 LVL4-5",IF(E39>0,"🟠 LVL3",IF(D39>0,"🟡 LVL2",IF(C39>0,"🟢 LVL1","⬜ LVL0")))) -> 🟡 LVL2 | H39: =1539+D39*12.25*(CONFIG!$B$28-1)*CONFIG!$B$61+MIN(E39,ROUND(E39*CONFIG!$B$60,0))*0.7*12.25*CONFIG!$B$29+MIN(E39,ROUND(E39*CONFIG!$B$60,0))*0.3*12.25*CONFIG!$B$30+F39*CONFIG!$B$57*12.25 -> 1688.5725 | I39: Outbreak declared
A40: 3 | B40: 7 | C40: =MIN(B40,3) -> 3 | D40: =MIN(MAX(B40-C40,0),4) -> 4 | E40: =MAX(B40-C40-D40,0) -> 0 | F40: =MAX(E40-ROUND(E40*CONFIG!$B$60,0),0) -> 0 | G40: =IF(F40>0,"🔴 LVL4-5",IF(E40>0,"🟠 LVL3",IF(D40>0,"🟡 LVL2",IF(C40>0,"🟢 LVL1","⬜ LVL0")))) -> 🟡 LVL2 | H40: =1539+D40*12.25*(CONFIG!$B$28-1)*CONFIG!$B$61+MIN(E40,ROUND(E40*CONFIG!$B$60,0))*0.7*12.25*CONFIG!$B$29+MIN(E40,ROUND(E40*CONFIG!$B$60,0))*0.3*12.25*CONFIG!$B$30+F40*CONFIG!$B$57*12.25 -> 2137.29 | I40: IPC active
A41: 4 | B41: 9 | C41: =MIN(B41,3) -> 3 | D41: =MIN(MAX(B41-C41,0),4) -> 4 | E41: =MAX(B41-C41-D41,0) -> 2 | F41: =MAX(E41-ROUND(E41*CONFIG!$B$60,0),0) -> 0 | G41: =IF(F41>0,"🔴 LVL4-5",IF(E41>0,"🟠 LVL3",IF(D41>0,"🟡 LVL2",IF(C41>0,"🟢 LVL1","⬜ LVL0")))) -> 🟠 LVL3 | H41: =1539+D41*12.25*(CONFIG!$B$28-1)*CONFIG!$B$61+MIN(E41,ROUND(E41*CONFIG!$B$60,0))*0.7*12.25*CONFIG!$B$29+MIN(E41,ROUND(E41*CONFIG!$B$60,0))*0.3*12.25*CONFIG!$B$30+F41*CONFIG!$B$57*12.25 -> 2720.39 | I41: PEAK
A42: 5 | B42: 10 | C42: =MIN(B42,3) -> 3 | D42: =MIN(MAX(B42-C42,0),4) -> 4 | E42: =MAX(B42-C42-D42,0) -> 3 | F42: =MAX(E42-ROUND(E42*CONFIG!$B$60,0),0) -> 0 | G42: =IF(F42>0,"🔴 LVL4-5",IF(E42>0,"🟠 LVL3",IF(D42>0,"🟡 LVL2",IF(C42>0,"🟢 LVL1","⬜ LVL0")))) -> 🟠 LVL3 | H42: =1539+D42*12.25*(CONFIG!$B$28-1)*CONFIG!$B$61+MIN(E42,ROUND(E42*CONFIG!$B$60,0))*0.7*12.25*CONFIG!$B$29+MIN(E42,ROUND(E42*CONFIG!$B$60,0))*0.3*12.25*CONFIG!$B$30+F42*CONFIG!$B$57*12.25 -> 3011.94 | I42: PEAK+1 Manager floor
A43: 6 | B43: 8 | C43: =MIN(B43,3) -> 3 | D43: =MIN(MAX(B43-C43,0),4) -> 4 | E43: =MAX(B43-C43-D43,0) -> 1 | F43: =MAX(E43-ROUND(E43*CONFIG!$B$60,0),0) -> 0 | G43: =IF(F43>0,"🔴 LVL4-5",IF(E43>0,"🟠 LVL3",IF(D43>0,"🟡 LVL2",IF(C43>0,"🟢 LVL1","⬜ LVL0")))) -> 🟠 LVL3 | H43: =1539+D43*12.25*(CONFIG!$B$28-1)*CONFIG!$B$61+MIN(E43,ROUND(E43*CONFIG!$B$60,0))*0.7*12.25*CONFIG!$B$29+MIN(E43,ROUND(E43*CONFIG!$B$60,0))*0.3*12.25*CONFIG!$B$30+F43*CONFIG!$B$57*12.25 -> 2428.84 | I43: First recoveries
A44: 7 | B44: 7 | C44: =MIN(B44,3) -> 3 | D44: =MIN(MAX(B44-C44,0),4) -> 4 | E44: =MAX(B44-C44-D44,0) -> 0 | F44: =MAX(E44-ROUND(E44*CONFIG!$B$60,0),0) -> 0 | G44: =IF(F44>0,"🔴 LVL4-5",IF(E44>0,"🟠 LVL3",IF(D44>0,"🟡 LVL2",IF(C44>0,"🟢 LVL1","⬜ LVL0")))) -> 🟡 LVL2 | H44: =1539+D44*12.25*(CONFIG!$B$28-1)*CONFIG!$B$61+MIN(E44,ROUND(E44*CONFIG!$B$60,0))*0.7*12.25*CONFIG!$B$29+MIN(E44,ROUND(E44*CONFIG!$B$60,0))*0.3*12.25*CONFIG!$B$30+F44*CONFIG!$B$57*12.25 -> 2137.29 | I44: Declining
A45: 8 | B45: 5 | C45: =MIN(B45,3) -> 3 | D45: =MIN(MAX(B45-C45,0),4) -> 2 | E45: =MAX(B45-C45-D45,0) -> 0 | F45: =MAX(E45-ROUND(E45*CONFIG!$B$60,0),0) -> 0 | G45: =IF(F45>0,"🔴 LVL4-5",IF(E45>0,"🟠 LVL3",IF(D45>0,"🟡 LVL2",IF(C45>0,"🟢 LVL1","⬜ LVL0")))) -> 🟡 LVL2 | H45: =1539+D45*12.25*(CONFIG!$B$28-1)*CONFIG!$B$61+MIN(E45,ROUND(E45*CONFIG!$B$60,0))*0.7*12.25*CONFIG!$B$29+MIN(E45,ROUND(E45*CONFIG!$B$60,0))*0.3*12.25*CONFIG!$B$30+F45*CONFIG!$B$57*12.25 -> 1838.145 | I45: Recovery
A46: 9 | B46: 4 | C46: =MIN(B46,3) -> 3 | D46: =MIN(MAX(B46-C46,0),4) -> 1 | E46: =MAX(B46-C46-D46,0) -> 0 | F46: =MAX(E46-ROUND(E46*CONFIG!$B$60,0),0) -> 0 | G46: =IF(F46>0,"🔴 LVL4-5",IF(E46>0,"🟠 LVL3",IF(D46>0,"🟡 LVL2",IF(C46>0,"🟢 LVL1","⬜ LVL0")))) -> 🟡 LVL2 | H46: =1539+D46*12.25*(CONFIG!$B$28-1)*CONFIG!$B$61+MIN(E46,ROUND(E46*CONFIG!$B$60,0))*0.7*12.25*CONFIG!$B$29+MIN(E46,ROUND(E46*CONFIG!$B$60,0))*0.3*12.25*CONFIG!$B$30+F46*CONFIG!$B$57*12.25 -> 1688.5725 | I46: Near-normal
A47: 10 | B47: 3 | C47: =MIN(B47,3) -> 3 | D47: =MIN(MAX(B47-C47,0),4) -> 0 | E47: =MAX(B47-C47-D47,0) -> 0 | F47: =MAX(E47-ROUND(E47*CONFIG!$B$60,0),0) -> 0 | G47: =IF(F47>0,"🔴 LVL4-5",IF(E47>0,"🟠 LVL3",IF(D47>0,"🟡 LVL2",IF(C47>0,"🟢 LVL1","⬜ LVL0")))) -> 🟢 LVL1 | H47: =1539+D47*12.25*(CONFIG!$B$28-1)*CONFIG!$B$61+MIN(E47,ROUND(E47*CONFIG!$B$60,0))*0.7*12.25*CONFIG!$B$29+MIN(E47,ROUND(E47*CONFIG!$B$60,0))*0.3*12.25*CONFIG!$B$30+F47*CONFIG!$B$57*12.25 -> 1539 | I47: Monitoring
A48: 11 | B48: 2 | C48: =MIN(B48,3) -> 2 | D48: =MIN(MAX(B48-C48,0),4) -> 0 | E48: =MAX(B48-C48-D48,0) -> 0 | F48: =MAX(E48-ROUND(E48*CONFIG!$B$60,0),0) -> 0 | G48: =IF(F48>0,"🔴 LVL4-5",IF(E48>0,"🟠 LVL3",IF(D48>0,"🟡 LVL2",IF(C48>0,"🟢 LVL1","⬜ LVL0")))) -> 🟢 LVL1 | H48: =1539+D48*12.25*(CONFIG!$B$28-1)*CONFIG!$B$61+MIN(E48,ROUND(E48*CONFIG!$B$60,0))*0.7*12.25*CONFIG!$B$29+MIN(E48,ROUND(E48*CONFIG!$B$60,0))*0.3*12.25*CONFIG!$B$30+F48*CONFIG!$B$57*12.25 -> 1539 | I48: Almost clear
A49: 12 | B49: 1 | C49: =MIN(B49,3) -> 1 | D49: =MIN(MAX(B49-C49,0),4) -> 0 | E49: =MAX(B49-C49-D49,0) -> 0 | F49: =MAX(E49-ROUND(E49*CONFIG!$B$60,0),0) -> 0 | G49: =IF(F49>0,"🔴 LVL4-5",IF(E49>0,"🟠 LVL3",IF(D49>0,"🟡 LVL2",IF(C49>0,"🟢 LVL1","⬜ LVL0")))) -> 🟢 LVL1 | H49: =1539+D49*12.25*(CONFIG!$B$28-1)*CONFIG!$B$61+MIN(E49,ROUND(E49*CONFIG!$B$60,0))*0.7*12.25*CONFIG!$B$29+MIN(E49,ROUND(E49*CONFIG!$B$60,0))*0.3*12.25*CONFIG!$B$30+F49*CONFIG!$B$57*12.25 -> 1539 | I49: Clearing
... A51: 14 | B51: 0 | C51: =MIN(B51,3) -> 0 | D51: =MIN(MAX(B51-C51,0),4) -> 0 | E51: =MAX(B51-C51-D51,0) -> 0 | F51: =MAX(E51-ROUND(E51*CONFIG!$B$60,0),0) -> 0 | G51: =IF(F51>0,"🔴 LVL4-5",IF(E51>0,"🟠 LVL3",IF(D51>0,"🟡 LVL2",IF(C51>0,"🟢 LVL1","⬜ LVL0")))) -> ⬜ LVL0 | H51: =1539+D51*12.25*(CONFIG!$B$28-1)*CONFIG!$B$61+MIN(E51,ROUND(E51*CONFIG!$B$60,0))*0.7*12.25*CONFIG!$B$29+MIN(E51,ROUND(E51*CONFIG!$B$60,0))*0.3*12.25*CONFIG!$B$30+F51*CONFIG!$B$57*12.25 -> 1539 | I51: Normal
...

Sheet CONFIG
A1: CARE HOME STAFFING SYSTEM v3.0
A2: SELF-ORGANIZING EDITION
A4: SETTING | B4: VALUE | C4: UNIT | D4: NOTES
A5: Roster Start Date | B5: 2025-01-06 | D5: Must be a Monday
A6: Cycle Length | B6: 14 | C6: days | D6: Panama rotation period
A8: SHIFT TIMES & HOURS
A9: Early Shift (E) | B9: 6 | C9: hours | D9: 08:00-14:00
A10: Late Shift (L) | B10: 6 | C10: hours | D10: 14:00-20:00
A11: Full Day (EL) | B11: 12.25 | C11: hours | D11: 07:45-20:00 (incl 15min handover)
A12: Night Shift (N) | B12: 12.25 | C12: hours | D12: 19:45-08:00 (incl 15min handover)
A14: HANDOVER & BREAKS
A15: Evening Handover | B15: 15 | C15: mins | D15: 19:45-20:00 (Day→Night overlap)
A16: Morning Handover | B16: 15 | C16: mins | D16: 07:45-08:00 (Night→Day overlap)
A17: Break Deduction | B17: 0 | C17: hours | D17: Breaks are PAID (care home requirement)
A19: MINIMUM STAFFING
A20: Early Min (Heads) | B20: 3 | C20: people | D20: Minimum on Early
A21: Early Min (Skill) | B21: 2 | C21: points | D21: Senior=1.0, Junior=0.5
A22: Late Min (Heads) | B22: 3 | C22: people | D22: Minimum on Late
A23: Late Min (Skill) | B23: 2 | C23: points | D23: Senior=1.0, Junior=0.5
A24: Night Min (Heads) | B24: 3 | C24: people | D24: Minimum on Night
A25: Night Min (Skill) | B25: 1.5 | C25: points | D25: At least 1 Senior
A27: OVERTIME & AGENCY
A28: OT Premium | B28: 2 | C28: £/hour | D28: Extra for OC/OT shifts
A29: Agency Rate (Day) | B29: 22 | C29: £/hour | D29: External day cover
A30: Agency Rate (Night) | B30: 28 | C30: £/hour | D30: External night cover (12hr)
A32: SAFETY LIMITS
A33: Max Consecutive Days | B33: 5 | C33: days | D33: Fatigue limit
A34: Max AL Same Day | B34: 2 | C34: people | D34: Coverage protection
A35: Float Retainer | B35: 50 | C35: £/week | D35: Standby payment
A37: ANNUAL LEAVE
A38: AL Entitlement | B38: 28 | C38: days/year | D38: Standard UK
A40: WEEKLY HOURS TARGETS
A41: FT Target (EL workers) | B41: 42.875 | C41: hours/week | D41: 3.5 shifts × 12.25hrs
A42: FT Target (E or L only) | B42: 36 | C42: hours/week | D42: 6 shifts avg
A43: Night FT Target | B43: 42.875 | C43: hours/week | D43: 3.5 shifts × 12.25hrs
A45: BANK HOLIDAY
A46: BH Premium | B46: 1.5 | C46: multiplier | D46: Applied to base rate on bank holidays
A48: SICKNESS ASSUMPTIONS
A49: Avg Sickness Rate | B49: 0.06 | C49: % | D49: 6% sector average (5-8% typical)
A50: Avg AL per day | B50: 1 | C50: people | D50: Typical daily AL overlap
...

Sheet STAFF_DB
A1: STAFF DATABASE - Single Source of Truth
A2: Add/remove staff here. ROSTER updates automatically.
A4: ID | B4: Name | C4: Role | D4: Team | E4: Pref | F4: Skill | G4: Rate | H4: Active | I4: Start Date | J4: Notes | K4: WTR Opt-Out
A5: S001 | B5: Alice Johnson | C5: Senior Carer | D5: Day A | E5: EL | F5: 1 | G5: 12.5 | H5: Y | I5: 2025-01-06 | K5: Y
A6: S002 | B6: Bob Smith | C6: Carer | D6: Day A | E6: EL | F6: 0.5 | G6: 11 | H6: Y | I6: 2025-01-06 | K6: Y
A7: S003 | B7: Carol Davis | C7: Senior Carer | D7: Day A | E7: EL | F7: 1 | G7: 12.5 | H7: Y | I7: 2025-01-06 | K7: Y
A8: S004 | B8: David Wilson | C8: Carer | D8: Day A | E8: EL | F8: 0.5 | G8: 11 | H8: Y | I8: 2025-01-06 | K8: Y
A9: S005 | B9: Emma Brown | C9: Team Lead | D9: Day A | E9: EL | F9: 1.5 | G9: 14 | H9: Y | I9: 2025-01-06 | K9: Y
A10: S006 | B10: Fiona Hart | C10: Carer | D10: Day A | E10: EL | F10: 0.5 | G10: 11 | H10: Y | I10: 2025-01-06 | K10: Y
A11: S007 | B11: George King | C11: Senior Carer | D11: Day A | E11: EL | F11: 1 | G11: 12.5 | H11: Y | I11: 2025-01-06 | K11: Y
A12: S008 | B12: Hannah Lee | C12: Senior Carer | D12: Day B | E12: EL | F12: 1 | G12: 12.5 | H12: Y | I12: 2025-01-06 | K12: Y
A13: S009 | B13: Ian Clark | C13: Carer | D13: Day B | E13: EL | F13: 0.5 | G13: 11 | H13: Y | I13: 2025-01-06 | K13: Y
A14: S010 | B14: Julia Martin | C14: Senior Carer | D14: Day B | E14: EL | F14: 1 | G14: 12.5 | H14: Y | I14: 2025-01-06 | K14: Y
A15: S011 | B15: Kevin White | C15: Carer | D15: Day B | E15: EL | F15: 0.5 | G15: 11 | H15: Y | I15: 2025-01-06 | K15: Y
A16: S012 | B16: Laura Adams | C16: Team Lead | D16: Day B | E16: EL | F16: 1.5 | G16: 14 | H16: Y | I16: 2025-01-06 | K16: Y
... A27: S023 | B27: Wendy Jones | C27: Float Carer | D27: Float | E27: ANY | F27: 0.5 | G27: 11.5 | H27: Y | I27: 2025-01-06 | K27: Y
A28: S024 | B28: Xena Price | C28: Carer (PT) | D28: Day A | E28: E | F28: 0.5 | G28: 10.5 | H28: Y | I28: 45663 | J28: Early only - school run | K28: Y
A29: S025 | B29: Yasmin Reed | C29: Senior (PT) | D29: Day B | E29: L | F29: 1 | G29: 12 | H29: Y | I29: 45663 | J29: Late only - prefers afternoons | K29: Y
A30: TEAM SUMMARY
A31: Day A | B31: =COUNTIFS(D5:D100,"Day A",H5:H100,"Y") -> 8
A32: Day B | B32: =COUNTIFS(D5:D100,"Day B",H5:H100,"Y") -> 8
A33: Night A | B33: =COUNTIFS(D5:D100,"Night A",H5:H100,"Y") -> 3
A34: Night B | B34: =COUNTIFS(D5:D100,"Night B",H5:H100,"Y") -> 3
A35: Float | B35: =COUNTIFS(D5:D100,"Float",H5:H100,"Y") -> 3
A36: TOTAL ACTIVE | B36: =COUNTIF(H5:H100,"Y") -> 25
A37: Part-Time (E/L) | B37: =COUNTIFS(E5:E100,"E",H5:H100,"Y")+COUNTIFS(E5:E100,"L",H5:H100,"Y") -> 2
A38: TOTAL ACTIVE | B38: =COUNTIF(H5:H100,"Y") -> 25

Sheet ROSTER
A1: DYNAMIC ROSTER - Self-Organizing
A2: Gold cells = "Agency Kill" targets (rested staff on short week) | E2: Week 1 | L2: Week 2 | S2: Week 3 | Z2: Week 4
A3: Name | B3: Team | C3: Pref | D3: Skill | E3: 06 Mon | F3: 07 Tue | G3: 08 Wed | H3: 09 Thu | I3: 10 Fri | J3: 11 Sat | K3: 12 Sun | L3: 13 Mon | M3: 14 Tue | N3: 15 Wed | O3: 16 Thu | P3: 17 Fri | Q3: 18 Sat | R3: 19 Sun | S3: 20 Mon | T3: 21 Tue | U3: 22 Wed | V3: 23 Thu | W3: 24 Fri | X3: 25 Sat | Y3: 26 Sun | Z3: 27 Mon | AA3: 28 Tue | AB3: 29 Wed | AC3: 30 Thu | AD3: 31 Fri | AE3: 01 Sat | AF3: 02 Sun | AG3: Rate | AH3: Total Hrs | AI3: Gross Pay | AJ3: OT Hrs | AK3: OT Pay | AL3: Week 1 | AM3: Week 2 | AN3: Status | AO3: BH Prem | AP3: Wk Avg Hrs | AQ3: WTR Check
A4: Alice Johnson | B4: Day A | C4: EL | D4: 1 | E4: EL | F4: EL | G4: OFF | H4: OFF | I4: EL | J4: EL | K4: EL | L4: OFF | M4: OFF | N4: EL | O4: EL | P4: OFF | Q4: OFF | R4: OFF | S4: EL | T4: EL | U4: OFF | V4: OFF | W4: EL | X4: EL | Y4: EL | Z4: OFF | AA4: OFF | AB4: EL | AC4: EL | AD4: OFF | AE4: OFF | AF4: OFF | AG4: 12.5 | AH4: =(COUNTIF(E4:AF4,"E")*CONFIG!$B$9+COUNTIF(E4:AF4,"L")*CONFIG!$B$10+COUNTIF(E4:AF4,"EL")*CONFIG!$B$11+COUNTIF(E4:AF4,"N")*CONFIG!$B$12+COUNTIF(E4:AF4,"OC-E")*CONFIG!$B$9+COUNTIF(E4:AF4,"OC-L")*CONFIG!$B$10+COUNTIF(E4:AF4,"OC-EL")*CONFIG!$B$11+COUNTIF(E4:AF4,"OC-N")*CONFIG!$B$12+COUNTIF(E4:AF4,"ADM")*CONFIG!$B$9+COUNTIF(E4:AF4,"TRN")*CONFIG!$B$9+COUNTIF(E4:AF4,"BH-D")*CONFIG!$B$11+COUNTIF(E4:AF4,"BH-N")*CONFIG!$B$12) -> 171.5 | AI4: =AH4*AG4 -> 2143.75 | AJ4: =(COUNTIF(E4:AF4,"OC-E")*CONFIG!$B$9+COUNTIF(E4:AF4,"OC-L")*CONFIG!$B$10+COUNTIF(E4:AF4,"OC-EL")*CONFIG!$B$11+COUNTIF(E4:AF4,"OC-N")*CONFIG!$B$12+COUNTIF(E4:AF4,"OT")*CONFIG!$B$9) -> 0 | AK4: =AJ4*CONFIG!$B$28 -> 0 | AL4: =(COUNTIF(E4:K4,"E")+COUNTIF(E4:K4,"L")+COUNTIF(E4:K4,"OC-E")+COUNTIF(E4:K4,"OC-L"))*6+(COUNTIF(E4:K4,"EL")+COUNTIF(E4:K4,"OC-EL")+COUNTIF(E4:K4,"BH-D"))*12.25+(COUNTIF(E4:K4,"N")+COUNTIF(E4:K4,"OC-N")+COUNTIF(E4:K4,"BH-N"))*12.25 -> 61.25 | AM4: =(COUNTIF(L4:R4,"E")+COUNTIF(L4:R4,"L")+COUNTIF(L4:R4,"OC-E")+COUNTIF(L4:R4,"OC-L"))*6+(COUNTIF(L4:R4,"EL")+COUNTIF(L4:R4,"OC-EL")+COUNTIF(L4:R4,"BH-D"))*12.25+(COUNTIF(L4:R4,"N")+COUNTIF(L4:R4,"OC-N")+COUNTIF(L4:R4,"BH-N"))*12.25 -> 24.5 | AN4: =IF(AL4<AM4,"Short W1",IF(AM4<AL4,"Short W2","Balanced")) -> Short W2 | AO4: =(COUNTIF(E4:AF4,"BH-D")*CONFIG!$B$11*AG4*(CONFIG!$B$46-1)+COUNTIF(E4:AF4,"BH-N")*CONFIG!$B$12*AG4*(CONFIG!$B$46-1)) -> 0 | AP4: =AH4/4 -> 42.875 | AQ4: =IF(AP4>48,"⚠️ >48hr WTR BREACH",IF(AP4>44,"🟡 HIGH","✅ OK")) -> ✅ OK
A5: Bob Smith | B5: Day A | C5: EL | D5: 0.5 | E5: EL | F5: EL | G5: OFF | H5: OFF | I5: EL | J5: EL | K5: EL | L5: OFF | M5: OFF | N5: EL | O5: EL | P5: OFF | Q5: OFF | R5: OFF | S5: EL | T5: EL | U5: OFF | V5: OFF | W5: EL | X5: EL | Y5: EL | Z5: OFF | AA5: OFF | AB5: EL | AC5: EL | AD5: OFF | AE5: OFF | AF5: OFF | AG5: 11 | AH5: =(COUNTIF(E5:AF5,"E")*CONFIG!$B$9+COUNTIF(E5:AF5,"L")*CONFIG!$B$10+COUNTIF(E5:AF5,"EL")*CONFIG!$B$11+COUNTIF(E5:AF5,"N")*CONFIG!$B$12+COUNTIF(E5:AF5,"OC-E")*CONFIG!$B$9+COUNTIF(E5:AF5,"OC-L")*CONFIG!$B$10+COUNTIF(E5:AF5,"OC-EL")*CONFIG!$B$11+COUNTIF(E5:AF5,"OC-N")*CONFIG!$B$12+COUNTIF(E5:AF5,"ADM")*CONFIG!$B$9+COUNTIF(E5:AF5,"TRN")*CONFIG!$B$9+COUNTIF(E5:AF5,"BH-D")*CONFIG!$B$11+COUNTIF(E5:AF5,"BH-N")*CONFIG!$B$12) -> 171.5 | AI5: =AH5*AG5 -> 1886.5 | AJ5: =(COUNTIF(E5:AF5,"OC-E")*CONFIG!$B$9+COUNTIF(E5:AF5,"OC-L")*CONFIG!$B$10+COUNTIF(E5:AF5,"OC-EL")*CONFIG!$B$11+COUNTIF(E5:AF5,"OC-N")*CONFIG!$B$12+COUNTIF(E5:AF5,"OT")*CONFIG!$B$9) -> 0 | AK5: =AJ5*CONFIG!$B$28 -> 0 | AL5: =(COUNTIF(E5:K5,"E")+COUNTIF(E5:K5,"L")+COUNTIF(E5:K5,"OC-E")+COUNTIF(E5:K5,"OC-L"))*6+(COUNTIF(E5:K5,"EL")+COUNTIF(E5:K5,"OC-EL")+COUNTIF(E5:K5,"BH-D"))*12.25+(COUNTIF(E5:K5,"N")+COUNTIF(E5:K5,"OC-N")+COUNTIF(E5:K5,"BH-N"))*12.25 -> 61.25 | AM5: =(COUNTIF(L5:R5,"E")+COUNTIF(L5:R5,"L")+COUNTIF(L5:R5,"OC-E")+COUNTIF(L5:R5,"OC-L"))*6+(COUNTIF(L5:R5,"EL")+COUNTIF(L5:R5,"OC-EL")+COUNTIF(L5:R5,"BH-D"))*12.25+(COUNTIF(L5:R5,"N")+COUNTIF(L5:R5,"OC-N")+COUNTIF(L5:R5,"BH-N"))*12.25 -> 24.5 | AN5: =IF(AL5<AM5,"Short W1",IF(AM5<AL5,"Short W2","Balanced")) -> Short W2 | AO5: =(COUNTIF(E5:AF5,"BH-D")*CONFIG!$B$11*AG5*(CONFIG!$B$46-1)+COUNTIF(E5:AF5,"BH-N")*CONFIG!$B$12*AG5*(CONFIG!$B$46-1)) -> 0 | AP5: =AH5/4 -> 42.875 | AQ5: =IF(AP5>48,"⚠️ >48hr WTR BREACH",IF(AP5>44,"🟡 HIGH","✅ OK")) -> ✅ OK
A6: Carol Davis | B6: Day A | C6: EL | D6: 1 | E6: EL | F6: EL | G6: OFF | H6: OFF | I6: EL | J6: EL | K6: EL | L6: OFF | M6: OFF | N6: EL | O6: EL | P6: OFF | Q6: OFF | R6: OFF | S6: EL | T6: EL | U6: OFF | V6: OFF | W6: EL | X6: EL | Y6: EL | Z6: OFF | AA6: OFF | AB6: EL | AC6: EL | AD6: OFF | AE6: OFF | AF6: OFF | AG6: 12.5 | AH6: =(COUNTIF(E6:AF6,"E")*CONFIG!$B$9+COUNTIF(E6:AF6,"L")*CONFIG!$B$10+COUNTIF(E6:AF6,"EL")*CONFIG!$B$11+COUNTIF(E6:AF6,"N")*CONFIG!$B$12+COUNTIF(E6:AF6,"OC-E")*CONFIG!$B$9+COUNTIF(E6:AF6,"OC-L")*CONFIG!$B$10+COUNTIF(E6:AF6,"OC-EL")*CONFIG!$B$11+COUNTIF(E6:AF6,"OC-N")*CONFIG!$B$12+COUNTIF(E6:AF6,"ADM")*CONFIG!$B$9+COUNTIF(E6:AF6,"TRN")*CONFIG!$B$9+COUNTIF(E6:AF6,"BH-D")*CONFIG!$B$11+COUNTIF(E6:AF6,"BH-N")*CONFIG!$B$12) -> 171.5 | AI6: =AH6*AG6 -> 2143.75 | AJ6: =(COUNTIF(E6:AF6,"OC-E")*CONFIG!$B$9+COUNTIF(E6:AF6,"OC-L")*CONFIG!$B$10+COUNTIF(E6:AF6,"OC-EL")*CONFIG!$B$11+COUNTIF(E6:AF6,"OC-N")*CONFIG!$B$12+COUNTIF(E6:AF6,"OT")*CONFIG!$B$9) -> 0 | AK6: =AJ6*CONFIG!$B$28 -> 0 | AL6: =(COUNTIF(E6:K6,"E")+COUNTIF(E6:K6,"L")+COUNTIF(E6:K6,"OC-E")+COUNTIF(E6:K6,"OC-L"))*6+(COUNTIF(E6:K6,"EL")+COUNTIF(E6:K6,"OC-EL")+COUNTIF(E6:K6,"BH-D"))*12.25+(COUNTIF(E6:K6,"N")+COUNTIF(E6:K6,"OC-N")+COUNTIF(E6:K6,"BH-N"))*12.25 -> 61.25 | AM6: =(COUNTIF(L6:R6,"E")+COUNTIF(L6:R6,"L")+COUNTIF(L6:R6,"OC-E")+COUNTIF(L6:R6,"OC-L"))*6+(COUNTIF(L6:R6,"EL")+COUNTIF(L6:R6,"OC-EL")+COUNTIF(L6:R6,"BH-D"))*12.25+(COUNTIF(L6:R6,"N")+COUNTIF(L6:R6,"OC-N")+COUNTIF(L6:R6,"BH-N"))*12.25 -> 24.5 | AN6: =IF(AL6<AM6,"Short W1",IF(AM6<AL6,"Short W2","Balanced")) -> Short W2 | AO6: =(COUNTIF(E6:AF6,"BH-D")*CONFIG!$B$11*AG6*(CONFIG!$B$46-1)+COUNTIF(E6:AF6,"BH-N")*CONFIG!$B$12*AG6*(CONFIG!$B$46-1)) -> 0 | AP6: =AH6/4 -> 42.875 | AQ6: =IF(AP6>48,"⚠️ >48hr WTR BREACH",IF(AP6>44,"🟡 HIGH","✅ OK")) -> ✅ OK
A7: David Wilson | B7: Day A | C7: EL | D7: 0.5 | E7: EL | F7: EL | G7: OFF | H7: OFF | I7: EL | J7: EL | K7: EL | L7: OFF | M7: OFF | N7: EL | O7: EL | P7: OFF | Q7: OFF | R7: OFF | S7: EL | T7: EL | U7: OFF | V7: OFF | W7: EL | X7: EL | Y7: EL | Z7: OFF | AA7: OFF | AB7: EL | AC7: EL | AD7: OFF | AE7: OFF | AF7: OFF | AG7: 11 | AH7: =(COUNTIF(E7:AF7,"E")*CONFIG!$B$9+COUNTIF(E7:AF7,"L")*CONFIG!$B$10+COUNTIF(E7:AF7,"EL")*CONFIG!$B$11+COUNTIF(E7:AF7,"N")*CONFIG!$B$12+COUNTIF(E7:AF7,"OC-E")*CONFIG!$B$9+COUNTIF(E7:AF7,"OC-L")*CONFIG!$B$10+COUNTIF(E7:AF7,"OC-EL")*CONFIG!$B$11+COUNTIF(E7:AF7,"OC-N")*CONFIG!$B$12+COUNTIF(E7:AF7,"ADM")*CONFIG!$B$9+COUNTIF(E7:AF7,"TRN")*CONFIG!$B$9+COUNTIF(E7:AF7,"BH-D")*CONFIG!$B$11+COUNTIF(E7:AF7,"BH-N")*CONFIG!$B$12) -> 171.5 | AI7: =AH7*AG7 -> 1886.5 | AJ7: =(COUNTIF(E7:AF7,"OC-E")*CONFIG!$B$9+COUNTIF(E7:AF7,"OC-L")*CONFIG!$B$10+COUNTIF(E7:AF7,"OC-EL")*CONFIG!$B$11+COUNTIF(E7:AF7,"OC-N")*CONFIG!$B$12+COUNTIF(E7:AF7,"OT")*CONFIG!$B$9) -> 0 | AK7: =AJ7*CONFIG!$B$28 -> 0 | AL7: =(COUNTIF(E7:K7,"E")+COUNTIF(E7:K7,"L")+COUNTIF(E7:K7,"OC-E")+COUNTIF(E7:K7,"OC-L"))*6+(COUNTIF(E7:K7,"EL")+COUNTIF(E7:K7,"OC-EL")+COUNTIF(E7:K7,"BH-D"))*12.25+(COUNTIF(E7:K7,"N")+COUNTIF(E7:K7,"OC-N")+COUNTIF(E7:K7,"BH-N"))*12.25 -> 61.25 | AM7: =(COUNTIF(L7:R7,"E")+COUNTIF(L7:R7,"L")+COUNTIF(L7:R7,"OC-E")+COUNTIF(L7:R7,"OC-L"))*6+(COUNTIF(L7:R7,"EL")+COUNTIF(L7:R7,"OC-EL")+COUNTIF(L7:R7,"BH-D"))*12.25+(COUNTIF(L7:R7,"N")+COUNTIF(L7:R7,"OC-N")+COUNTIF(L7:R7,"BH-N"))*12.25 -> 24.5 | AN7: =IF(AL7<AM7,"Short W1",IF(AM7<AL7,"Short W2","Balanced")) -> Short W2 | AO7: =(COUNTIF(E7:AF7,"BH-D")*CONFIG!$B$11*AG7*(CONFIG!$B$46-1)+COUNTIF(E7:AF7,"BH-N")*CONFIG!$B$12*AG7*(CONFIG!$B$46-1)) -> 0 | AP7: =AH7/4 -> 42.875 | AQ7: =IF(AP7>48,"⚠️ >48hr WTR BREACH",IF(AP7>44,"🟡 HIGH","✅ OK")) -> ✅ OK
A8: Emma Brown | B8: Day A | C8: EL | D8: 1.5 | E8: EL | F8: EL | G8: OFF | H8: OFF | I8: EL | J8: EL | K8: EL | L8: OFF | M8: OFF | N8: EL | O8: EL | P8: OFF | Q8: OFF | R8: OFF | S8: EL | T8: EL | U8: OFF | V8: OFF | W8: EL | X8: EL | Y8: EL | Z8: OFF | AA8: OFF | AB8: EL | AC8: EL | AD8: OFF | AE8: OFF | AF8: OFF | AG8: 14 | AH8: =(COUNTIF(E8:AF8,"E")*CONFIG!$B$9+COUNTIF(E8:AF8,"L")*CONFIG!$B$10+COUNTIF(E8:AF8,"EL")*CONFIG!$B$11+COUNTIF(E8:AF8,"N")*CONFIG!$B$12+COUNTIF(E8:AF8,"OC-E")*CONFIG!$B$9+COUNTIF(E8:AF8,"OC-L")*CONFIG!$B$10+COUNTIF(E8:AF8,"OC-EL")*CONFIG!$B$11+COUNTIF(E8:AF8,"OC-N")*CONFIG!$B$12+COUNTIF(E8:AF8,"ADM")*CONFIG!$B$9+COUNTIF(E8:AF8,"TRN")*CONFIG!$B$9+COUNTIF(E8:AF8,"BH-D")*CONFIG!$B$11+COUNTIF(E8:AF8,"BH-N")*CONFIG!$B$12) -> 171.5 | AI8: =AH8*AG8 -> 2401 | AJ8: =(COUNTIF(E8:AF8,"OC-E")*CONFIG!$B$9+COUNTIF(E8:AF8,"OC-L")*CONFIG!$B$10+COUNTIF(E8:AF8,"OC-EL")*CONFIG!$B$11+COUNTIF(E8:AF8,"OC-N")*CONFIG!$B$12+COUNTIF(E8:AF8,"OT")*CONFIG!$B$9) -> 0 | AK8: =AJ8*CONFIG!$B$28 -> 0 | AL8: =(COUNTIF(E8:K8,"E")+COUNTIF(E8:K8,"L")+COUNTIF(E8:K8,"OC-E")+COUNTIF(E8:K8,"OC-L"))*6+(COUNTIF(E8:K8,"EL")+COUNTIF(E8:K8,"OC-EL")+COUNTIF(E8:K8,"BH-D"))*12.25+(COUNTIF(E8:K8,"N")+COUNTIF(E8:K8,"OC-N")+COUNTIF(E8:K8,"BH-N"))*12.25 -> 61.25 | AM8: =(COUNTIF(L8:R8,"E")+COUNTIF(L8:R8,"L")+COUNTIF(L8:R8,"OC-E")+COUNTIF(L8:R8,"OC-L"))*6+(COUNTIF(L8:R8,"EL")+COUNTIF(L8:R8,"OC-EL")+COUNTIF(L8:R8,"BH-D"))*12.25+(COUNTIF(L8:R8,"N")+COUNTIF(L8:R8,"OC-N")+COUNTIF(L8:R8,"BH-N"))*12.25 -> 24.5 | AN8: =IF(AL8<AM8,"Short W1",IF(AM8<AL8,"Short W2","Balanced")) -> Short W2 | AO8: =(COUNTIF(E8:AF8,"BH-D")*CONFIG!$B$11*AG8*(CONFIG!$B$46-1)+COUNTIF(E8:AF8,"BH-N")*CONFIG!$B$12*AG8*(CONFIG!$B$46-1)) -> 0 | AP8: =AH8/4 -> 42.875 | AQ8: =IF(AP8>48,"⚠️ >48hr WTR BREACH",IF(AP8>44,"🟡 HIGH","✅ OK")) -> ✅ OK
A9: Fiona Hart | B9: Day A | C9: EL | D9: 0.5 | E9: EL | F9: EL | G9: OFF | H9: OFF | I9: EL | J9: EL | K9: EL | L9: OFF | M9: OFF | N9: EL | O9: EL | P9: OFF | Q9: OFF | R9: OFF | S9: EL | T9: EL | U9: OFF | V9: OFF | W9: EL | X9: EL | Y9: EL | Z9: OFF | AA9: OFF | AB9: EL | AC9: EL | AD9: OFF | AE9: OFF | AF9: OFF | AG9: 11 | AH9: =(COUNTIF(E9:AF9,"E")*CONFIG!$B$9+COUNTIF(E9:AF9,"L")*CONFIG!$B$10+COUNTIF(E9:AF9,"EL")*CONFIG!$B$11+COUNTIF(E9:AF9,"N")*CONFIG!$B$12+COUNTIF(E9:AF9,"OC-E")*CONFIG!$B$9+COUNTIF(E9:AF9,"OC-L")*CONFIG!$B$10+COUNTIF(E9:AF9,"OC-EL")*CONFIG!$B$11+COUNTIF(E9:AF9,"OC-N")*CONFIG!$B$12+COUNTIF(E9:AF9,"ADM")*CONFIG!$B$9+COUNTIF(E9:AF9,"TRN")*CONFIG!$B$9+COUNTIF(E9:AF9,"BH-D")*CONFIG!$B$11+COUNTIF(E9:AF9,"BH-N")*CONFIG!$B$12) -> 171.5 | AI9: =AH9*AG9 -> 1886.5 | AJ9: =(COUNTIF(E9:AF9,"OC-E")*CONFIG!$B$9+COUNTIF(E9:AF9,"OC-L")*CONFIG!$B$10+COUNTIF(E9:AF9,"OC-EL")*CONFIG!$B$11+COUNTIF(E9:AF9,"OC-N")*CONFIG!$B$12+COUNTIF(E9:AF9,"OT")*CONFIG!$B$9) -> 0 | AK9: =AJ9*CONFIG!$B$28 -> 0 | AL9: =(COUNTIF(E9:K9,"E")+COUNTIF(E9:K9,"L")+COUNTIF(E9:K9,"OC-E")+COUNTIF(E9:K9,"OC-L"))*6+(COUNTIF(E9:K9,"EL")+COUNTIF(E9:K9,"OC-EL")+COUNTIF(E9:K9,"BH-D"))*12.25+(COUNTIF(E9:K9,"N")+COUNTIF(E9:K9,"OC-N")+COUNTIF(E9:K9,"BH-N"))*12.25 -> 61.25 | AM9: =(COUNTIF(L9:R9,"E")+COUNTIF(L9:R9,"L")+COUNTIF(L9:R9,"OC-E")+COUNTIF(L9:R9,"OC-L"))*6+(COUNTIF(L9:R9,"EL")+COUNTIF(L9:R9,"OC-EL")+COUNTIF(L9:R9,"BH-D"))*12.25+(COUNTIF(L9:R9,"N")+COUNTIF(L9:R9,"OC-N")+COUNTIF(L9:R9,"BH-N"))*12.25 -> 24.5 | AN9: =IF(AL9<AM9,"Short W1",IF(AM9<AL9,"Short W2","Balanced")) -> Short W2 | AO9: =(COUNTIF(E9:AF9,"BH-D")*CONFIG!$B$11*AG9*(CONFIG!$B$46-1)+COUNTIF(E9:AF9,"BH-N")*CONFIG!$B$12*AG9*(CONFIG!$B$46-1)) -> 0 | AP9: =AH9/4 -> 42.875 | AQ9: =IF(AP9>48,"⚠️ >48hr WTR BREACH",IF(AP9>44,"🟡 HIGH","✅ OK")) -> ✅ OK
A10: George King | B10: Day A | C10: EL | D10: 1 | E10: EL | F10: EL | G10: OFF | H10: OFF | I10: EL | J10: EL | K10: EL | L10: OFF | M10: OFF | N10: EL | O10: EL | P10: OFF | Q10: OFF | R10: OFF | S10: EL | T10: EL | U10: OFF | V10: OFF | W10: EL | X10: EL | Y10: EL | Z10: OFF | AA10: OFF | AB10: EL | AC10: EL | AD10: OFF | AE10: OFF | AF10: OFF | AG10: 12.5 | AH10: =(COUNTIF(E10:AF10,"E")*CONFIG!$B$9+COUNTIF(E10:AF10,"L")*CONFIG!$B$10+COUNTIF(E10:AF10,"EL")*CONFIG!$B$11+COUNTIF(E10:AF10,"N")*CONFIG!$B$12+COUNTIF(E10:AF10,"OC-E")*CONFIG!$B$9+COUNTIF(E10:AF10,"OC-L")*CONFIG!$B$10+COUNTIF(E10:AF10,"OC-EL")*CONFIG!$B$11+COUNTIF(E10:AF10,"OC-N")*CONFIG!$B$12+COUNTIF(E10:AF10,"ADM")*CONFIG!$B$9+COUNTIF(E10:AF10,"TRN")*CONFIG!$B$9+COUNTIF(E10:AF10,"BH-D")*CONFIG!$B$11+COUNTIF(E10:AF10,"BH-N")*CONFIG!$B$12) -> 171.5 | AI10: =AH10*AG10 -> 2143.75 | AJ10: =(COUNTIF(E10:AF10,"OC-E")*CONFIG!$B$9+COUNTIF(E10:AF10,"OC-L")*CONFIG!$B$10+COUNTIF(E10:AF10,"OC-EL")*CONFIG!$B$11+COUNTIF(E10:AF10,"OC-N")*CONFIG!$B$12+COUNTIF(E10:AF10,"OT")*CONFIG!$B$9) -> 0 | AK10: =AJ10*CONFIG!$B$28 -> 0 | AL10: =(COUNTIF(E10:K10,"E")+COUNTIF(E10:K10,"L")+COUNTIF(E10:K10,"OC-E")+COUNTIF(E10:K10,"OC-L"))*6+(COUNTIF(E10:K10,"EL")+COUNTIF(E10:K10,"OC-EL")+COUNTIF(E10:K10,"BH-D"))*12.25+(COUNTIF(E10:K10,"N")+COUNTIF(E10:K10,"OC-N")+COUNTIF(E10:K10,"BH-N"))*12.25 -> 61.25 | AM10: =(COUNTIF(L10:R10,"E")+COUNTIF(L10:R10,"L")+COUNTIF(L10:R10,"OC-E")+COUNTIF(L10:R10,"OC-L"))*6+(COUNTIF(L10:R10,"EL")+COUNTIF(L10:R10,"OC-EL")+COUNTIF(L10:R10,"BH-D"))*12.25+(COUNTIF(L10:R10,"N")+COUNTIF(L10:R10,"OC-N")+COUNTIF(L10:R10,"BH-N"))*12.25 -> 24.5 | AN10: =IF(AL10<AM10,"Short W1",IF(AM10<AL10,"Short W2","Balanced")) -> Short W2 | AO10: =(COUNTIF(E10:AF10,"BH-D")*CONFIG!$B$11*AG10*(CONFIG!$B$46-1)+COUNTIF(E10:AF10,"BH-N")*CONFIG!$B$12*AG10*(CONFIG!$B$46-1)) -> 0 | AP10: =AH10/4 -> 42.875 | AQ10: =IF(AP10>48,"⚠️ >48hr WTR BREACH",IF(AP10>44,"🟡 HIGH","✅ OK")) -> ✅ OK
A11: Hannah Lee | B11: Day B | C11: EL | D11: 1 | E11: OFF | F11: OFF | G11: EL | H11: EL | I11: OFF | J11: OFF | K11: OFF | L11: EL | M11: EL | N11: OFF | O11: OFF | P11: EL | Q11: EL | R11: EL | S11: OFF | T11: OFF | U11: EL | V11: EL | W11: OFF | X11: OFF | Y11: OFF | Z11: EL | AA11: EL | AB11: OFF | AC11: OFF | AD11: EL | AE11: EL | AF11: EL | AG11: 12.5 | AH11: =(COUNTIF(E11:AF11,"E")*CONFIG!$B$9+COUNTIF(E11:AF11,"L")*CONFIG!$B$10+COUNTIF(E11:AF11,"EL")*CONFIG!$B$11+COUNTIF(E11:AF11,"N")*CONFIG!$B$12+COUNTIF(E11:AF11,"OC-E")*CONFIG!$B$9+COUNTIF(E11:AF11,"OC-L")*CONFIG!$B$10+COUNTIF(E11:AF11,"OC-EL")*CONFIG!$B$11+COUNTIF(E11:AF11,"OC-N")*CONFIG!$B$12+COUNTIF(E11:AF11,"ADM")*CONFIG!$B$9+COUNTIF(E11:AF11,"TRN")*CONFIG!$B$9+COUNTIF(E11:AF11,"BH-D")*CONFIG!$B$11+COUNTIF(E11:AF11,"BH-N")*CONFIG!$B$12) -> 171.5 | AI11: =AH11*AG11 -> 2143.75 | AJ11: =(COUNTIF(E11:AF11,"OC-E")*CONFIG!$B$9+COUNTIF(E11:AF11,"OC-L")*CONFIG!$B$10+COUNTIF(E11:AF11,"OC-EL")*CONFIG!$B$11+COUNTIF(E11:AF11,"OC-N")*CONFIG!$B$12+COUNTIF(E11:AF11,"OT")*CONFIG!$B$9) -> 0 | AK11: =AJ11*CONFIG!$B$28 -> 0 | AL11: =(COUNTIF(E11:K11,"E")+COUNTIF(E11:K11,"L")+COUNTIF(E11:K11,"OC-E")+COUNTIF(E11:K11,"OC-L"))*6+(COUNTIF(E11:K11,"EL")+COUNTIF(E11:K11,"OC-EL")+COUNTIF(E11:K11,"BH-D"))*12.25+(COUNTIF(E11:K11,"N")+COUNTIF(E11:K11,"OC-N")+COUNTIF(E11:K11,"BH-N"))*12.25 -> 24.5 | AM11: =(COUNTIF(L11:R11,"E")+COUNTIF(L11:R11,"L")+COUNTIF(L11:R11,"OC-E")+COUNTIF(L11:R11,"OC-L"))*6+(COUNTIF(L11:R11,"EL")+COUNTIF(L11:R11,"OC-EL")+COUNTIF(L11:R11,"BH-D"))*12.25+(COUNTIF(L11:R11,"N")+COUNTIF(L11:R11,"OC-N")+COUNTIF(L11:R11,"BH-N"))*12.25 -> 61.25 | AN11: =IF(AL11<AM11,"Short W1",IF(AM11<AL11,"Short W2","Balanced")) -> Short W1 | AO11: =(COUNTIF(E11:AF11,"BH-D")*CONFIG!$B$11*AG11*(CONFIG!$B$46-1)+COUNTIF(E11:AF11,"BH-N")*CONFIG!$B$12*AG11*(CONFIG!$B$46-1)) -> 0 | AP11: =AH11/4 -> 42.875 | AQ11: =IF(AP11>48,"⚠️ >48hr WTR BREACH",IF(AP11>44,"🟡 HIGH","✅ OK")) -> ✅ OK
A12: Ian Clark | B12: Day B | C12: EL | D12: 0.5 | E12: OFF | F12: OFF | G12: EL | H12: EL | I12: OFF | J12: OFF | K12: OFF | L12: EL | M12: EL | N12: OFF | O12: OFF | P12: EL | Q12: EL | R12: EL | S12: OFF | T12: OFF | U12: EL | V12: EL | W12: OFF | X12: OFF | Y12: OFF | Z12: EL | AA12: EL | AB12: OFF | AC12: OFF | AD12: EL | AE12: EL | AF12: EL | AG12: 11 | AH12: =(COUNTIF(E12:AF12,"E")*CONFIG!$B$9+COUNTIF(E12:AF12,"L")*CONFIG!$B$10+COUNTIF(E12:AF12,"EL")*CONFIG!$B$11+COUNTIF(E12:AF12,"N")*CONFIG!$B$12+COUNTIF(E12:AF12,"OC-E")*CONFIG!$B$9+COUNTIF(E12:AF12,"OC-L")*CONFIG!$B$10+COUNTIF(E12:AF12,"OC-EL")*CONFIG!$B$11+COUNTIF(E12:AF12,"OC-N")*CONFIG!$B$12+COUNTIF(E12:AF12,"ADM")*CONFIG!$B$9+COUNTIF(E12:AF12,"TRN")*CONFIG!$B$9+COUNTIF(E12:AF12,"BH-D")*CONFIG!$B$11+COUNTIF(E12:AF12,"BH-N")*CONFIG!$B$12) -> 171.5 | AI12: =AH12*AG12 -> 1886.5 | AJ12: =(COUNTIF(E12:AF12,"OC-E")*CONFIG!$B$9+COUNTIF(E12:AF12,"OC-L")*CONFIG!$B$10+COUNTIF(E12:AF12,"OC-EL")*CONFIG!$B$11+COUNTIF(E12:AF12,"OC-N")*CONFIG!$B$12+COUNTIF(E12:AF12,"OT")*CONFIG!$B$9) -> 0 | AK12: =AJ12*CONFIG!$B$28 -> 0 | AL12: =(COUNTIF(E12:K12,"E")+COUNTIF(E12:K12,"L")+COUNTIF(E12:K12,"OC-E")+COUNTIF(E12:K12,"OC-L"))*6+(COUNTIF(E12:K12,"EL")+COUNTIF(E12:K12,"OC-EL")+COUNTIF(E12:K12,"BH-D"))*12.25+(COUNTIF(E12:K12,"N")+COUNTIF(E12:K12,"OC-N")+COUNTIF(E12:K12,"BH-N"))*12.25 -> 24.5 | AM12: =(COUNTIF(L12:R12,"E")+COUNTIF(L12:R12,"L")+COUNTIF(L12:R12,"OC-E")+COUNTIF(L12:R12,"OC-L"))*6+(COUNTIF(L12:R12,"EL")+COUNTIF(L12:R12,"OC-EL")+COUNTIF(L12:R12,"BH-D"))*12.25+(COUNTIF(L12:R12,"N")+COUNTIF(L12:R12,"OC-N")+COUNTIF(L12:R12,"BH-N"))*12.25 -> 61.25 | AN12: =IF(AL12<AM12,"Short W1",IF(AM12<AL12,"Short W2","Balanced")) -> Short W1 | AO12: =(COUNTIF(E12:AF12,"BH-D")*CONFIG!$B$11*AG12*(CONFIG!$B$46-1)+COUNTIF(E12:AF12,"BH-N")*CONFIG!$B$12*AG12*(CONFIG!$B$46-1)) -> 0 | AP12: =AH12/4 -> 42.875 | AQ12: =IF(AP12>48,"⚠️ >48hr WTR BREACH",IF(AP12>44,"🟡 HIGH","✅ OK")) -> ✅ OK
A13: Julia Martin | B13: Day B | C13: EL | D13: 1 | E13: OFF | F13: OFF | G13: EL | H13: EL | I13: OFF | J13: OFF | K13: OFF | L13: EL | M13: EL | N13: OFF | O13: OFF | P13: EL | Q13: EL | R13: EL | S13: OFF | T13: OFF | U13: EL | V13: EL | W13: OFF | X13: OFF | Y13: OFF | Z13: EL | AA13: EL | AB13: OFF | AC13: OFF | AD13: EL | AE13: EL | AF13: EL | AG13: 12.5 | AH13: =(COUNTIF(E13:AF13,"E")*CONFIG!$B$9+COUNTIF(E13:AF13,"L")*CONFIG!$B$10+COUNTIF(E13:AF13,"EL")*CONFIG!$B$11+COUNTIF(E13:AF13,"N")*CONFIG!$B$12+COUNTIF(E13:AF13,"OC-E")*CONFIG!$B$9+COUNTIF(E13:AF13,"OC-L")*CONFIG!$B$10+COUNTIF(E13:AF13,"OC-EL")*CONFIG!$B$11+COUNTIF(E13:AF13,"OC-N")*CONFIG!$B$12+COUNTIF(E13:AF13,"ADM")*CONFIG!$B$9+COUNTIF(E13:AF13,"TRN")*CONFIG!$B$9+COUNTIF(E13:AF13,"BH-D")*CONFIG!$B$11+COUNTIF(E13:AF13,"BH-N")*CONFIG!$B$12) -> 171.5 | AI13: =AH13*AG13 -> 2143.75 | AJ13: =(COUNTIF(E13:AF13,"OC-E")*CONFIG!$B$9+COUNTIF(E13:AF13,"OC-L")*CONFIG!$B$10+COUNTIF(E13:AF13,"OC-EL")*CONFIG!$B$11+COUNTIF(E13:AF13,"OC-N")*CONFIG!$B$12+COUNTIF(E13:AF13,"OT")*CONFIG!$B$9) -> 0 | AK13: =AJ13*CONFIG!$B$28 -> 0 | AL13: =(COUNTIF(E13:K13,"E")+COUNTIF(E13:K13,"L")+COUNTIF(E13:K13,"OC-E")+COUNTIF(E13:K13,"OC-L"))*6+(COUNTIF(E13:K13,"EL")+COUNTIF(E13:K13,"OC-EL")+COUNTIF(E13:K13,"BH-D"))*12.25+(COUNTIF(E13:K13,"N")+COUNTIF(E13:K13,"OC-N")+COUNTIF(E13:K13,"BH-N"))*12.25 -> 24.5 | AM13: =(COUNTIF(L13:R13,"E")+COUNTIF(L13:R13,"L")+COUNTIF(L13:R13,"OC-E")+COUNTIF(L13:R13,"OC-L"))*6+(COUNTIF(L13:R13,"EL")+COUNTIF(L13:R13,"OC-EL")+COUNTIF(L13:R13,"BH-D"))*12.25+(COUNTIF(L13:R13,"N")+COUNTIF(L13:R13,"OC-N")+COUNTIF(L13:R13,"BH-N"))*12.25 -> 61.25 | AN13: =IF(AL13<AM13,"Short W1",IF(AM13<AL13,"Short W2","Balanced")) -> Short W1 | AO13: =(COUNTIF(E13:AF13,"BH-D")*CONFIG!$B$11*AG13*(CONFIG!$B$46-1)+COUNTIF(E13:AF13,"BH-N")*CONFIG!$B$12*AG13*(CONFIG!$B$46-1)) -> 0 | AP13: =AH13/4 -> 42.875 | AQ13: =IF(AP13>48,"⚠️ >48hr WTR BREACH",IF(AP13>44,"🟡 HIGH","✅ OK")) -> ✅ OK
A14: Kevin White | B14: Day B | C14: EL | D14: 0.5 | E14: OFF | F14: OFF | G14: EL | H14: EL | I14: OFF | J14: OFF | K14: OFF | L14: EL | M14: EL | N14: OFF | O14: OFF | P14: EL | Q14: EL | R14: EL | S14: OFF | T14: OFF | U14: EL | V14: EL | W14: OFF | X14: OFF | Y14: OFF | Z14: EL | AA14: EL | AB14: OFF | AC14: OFF | AD14: EL | AE14: EL | AF14: EL | AG14: 11 | AH14: =(COUNTIF(E14:AF14,"E")*CONFIG!$B$9+COUNTIF(E14:AF14,"L")*CONFIG!$B$10+COUNTIF(E14:AF14,"EL")*CONFIG!$B$11+COUNTIF(E14:AF14,"N")*CONFIG!$B$12+COUNTIF(E14:AF14,"OC-E")*CONFIG!$B$9+COUNTIF(E14:AF14,"OC-L")*CONFIG!$B$10+COUNTIF(E14:AF14,"OC-EL")*CONFIG!$B$11+COUNTIF(E14:AF14,"OC-N")*CONFIG!$B$12+COUNTIF(E14:AF14,"ADM")*CONFIG!$B$9+COUNTIF(E14:AF14,"TRN")*CONFIG!$B$9+COUNTIF(E14:AF14,"BH-D")*CONFIG!$B$11+COUNTIF(E14:AF14,"BH-N")*CONFIG!$B$12) -> 171.5 | AI14: =AH14*AG14 -> 1886.5 | AJ14: =(COUNTIF(E14:AF14,"OC-E")*CONFIG!$B$9+COUNTIF(E14:AF14,"OC-L")*CONFIG!$B$10+COUNTIF(E14:AF14,"OC-EL")*CONFIG!$B$11+COUNTIF(E14:AF14,"OC-N")*CONFIG!$B$12+COUNTIF(E14:AF14,"OT")*CONFIG!$B$9) -> 0 | AK14: =AJ14*CONFIG!$B$28 -> 0 | AL14: =(COUNTIF(E14:K14,"E")+COUNTIF(E14:K14,"L")+COUNTIF(E14:K14,"OC-E")+COUNTIF(E14:K14,"OC-L"))*6+(COUNTIF(E14:K14,"EL")+COUNTIF(E14:K14,"OC-EL")+COUNTIF(E14:K14,"BH-D"))*12.25+(COUNTIF(E14:K14,"N")+COUNTIF(E14:K14,"OC-N")+COUNTIF(E14:K14,"BH-N"))*12.25 -> 24.5 | AM14: =(COUNTIF(L14:R14,"E")+COUNTIF(L14:R14,"L")+COUNTIF(L14:R14,"OC-E")+COUNTIF(L14:R14,"OC-L"))*6+(COUNTIF(L14:R14,"EL")+COUNTIF(L14:R14,"OC-EL")+COUNTIF(L14:R14,"BH-D"))*12.25+(COUNTIF(L14:R14,"N")+COUNTIF(L14:R14,"OC-N")+COUNTIF(L14:R14,"BH-N"))*12.25 -> 61.25 | AN14: =IF(AL14<AM14,"Short W1",IF(AM14<AL14,"Short W2","Balanced")) -> Short W1 | AO14: =(COUNTIF(E14:AF14,"BH-D")*CONFIG!$B$11*AG14*(CONFIG!$B$46-1)+COUNTIF(E14:AF14,"BH-N")*CONFIG!$B$12*AG14*(CONFIG!$B$46-1)) -> 0 | AP14: =AH14/4 -> 42.875 | AQ14: =IF(AP14>48,"⚠️ >48hr WTR BREACH",IF(AP14>44,"🟡 HIGH","✅ OK")) -> ✅ OK
A15: Laura Adams | B15: Day B | C15: EL | D15: 1.5 | E15: OFF | F15: OFF | G15: EL | H15: EL | I15: OFF | J15: OFF | K15: OFF | L15: EL | M15: EL | N15: OFF | O15: OFF | P15: EL | Q15: EL | R15: EL | S15: OFF | T15: OFF | U15: EL | V15: EL | W15: OFF | X15: OFF | Y15: OFF | Z15: EL | AA15: EL | AB15: OFF | AC15: OFF | AD15: EL | AE15: EL | AF15: EL | AG15: 14 | AH15: =(COUNTIF(E15:AF15,"E")*CONFIG!$B$9+COUNTIF(E15:AF15,"L")*CONFIG!$B$10+COUNTIF(E15:AF15,"EL")*CONFIG!$B$11+COUNTIF(E15:AF15,"N")*CONFIG!$B$12+COUNTIF(E15:AF15,"OC-E")*CONFIG!$B$9+COUNTIF(E15:AF15,"OC-L")*CONFIG!$B$10+COUNTIF(E15:AF15,"OC-EL")*CONFIG!$B$11+COUNTIF(E15:AF15,"OC-N")*CONFIG!$B$12+COUNTIF(E15:AF15,"ADM")*CONFIG!$B$9+COUNTIF(E15:AF15,"TRN")*CONFIG!$B$9+COUNTIF(E15:AF15,"BH-D")*CONFIG!$B$11+COUNTIF(E15:AF15,"BH-N")*CONFIG!$B$12) -> 171.5 | AI15: =AH15*AG15 -> 2401 | AJ15: =(COUNTIF(E15:AF15,"OC-E")*CONFIG!$B$9+COUNTIF(E15:AF15,"OC-L")*CONFIG!$B$10+COUNTIF(E15:AF15,"OC-EL")*CONFIG!$B$11+COUNTIF(E15:AF15,"OC-N")*CONFIG!$B$12+COUNTIF(E15:AF15,"OT")*CONFIG!$B$9) -> 0 | AK15: =AJ15*CONFIG!$B$28 -> 0 | AL15: =(COUNTIF(E15:K15,"E")+COUNTIF(E15:K15,"L")+COUNTIF(E15:K15,"OC-E")+COUNTIF(E15:K15,"OC-L"))*6+(COUNTIF(E15:K15,"EL")+COUNTIF(E15:K15,"OC-EL")+COUNTIF(E15:K15,"BH-D"))*12.25+(COUNTIF(E15:K15,"N")+COUNTIF(E15:K15,"OC-N")+COUNTIF(E15:K15,"BH-N"))*12.25 -> 24.5 | AM15: =(COUNTIF(L15:R15,"E")+COUNTIF(L15:R15,"L")+COUNTIF(L15:R15,"OC-E")+COUNTIF(L15:R15,"OC-L"))*6+(COUNTIF(L15:R15,"EL")+COUNTIF(L15:R15,"OC-EL")+COUNTIF(L15:R15,"BH-D"))*12.25+(COUNTIF(L15:R15,"N")+COUNTIF(L15:R15,"OC-N")+COUNTIF(L15:R15,"BH-N"))*12.25 -> 61.25 | AN15: =IF(AL15<AM15,"Short W1",IF(AM15<AL15,"Short W2","Balanced")) -> Short W1 | AO15: =(COUNTIF(E15:AF15,"BH-D")*CONFIG!$B$11*AG15*(CONFIG!$B$46-1)+COUNTIF(E15:AF15,"BH-N")*CONFIG!$B$12*AG15*(CONFIG!$B$46-1)) -> 0 | AP15: =AH15/4 -> 42.875 | AQ15: =IF(AP15>48,"⚠️ >48hr WTR BREACH",IF(AP15>44,"🟡 HIGH","✅ OK")) -> ✅ OK
... A28: Yasmin Reed | B28: Day B | C28: L | D28: 1 | E28: OFF | F28: OFF | G28: L | H28: L | I28: OFF | J28: OFF | K28: OFF | L28: L | M28: L | N28: OFF | O28: OFF | P28: L | Q28: L | R28: L | S28: OFF | T28: OFF | U28: L | V28: L | W28: OFF | X28: OFF | Y28: OFF | Z28: L | AA28: L | AB28: OFF | AC28: OFF | AD28: L | AE28: L | AF28: L | AG28: 12 | AH28: =(COUNTIF(E28:AF28,"E")*CONFIG!$B$9+COUNTIF(E28:AF28,"L")*CONFIG!$B$10+COUNTIF(E28:AF28,"EL")*CONFIG!$B$11+COUNTIF(E28:AF28,"N")*CONFIG!$B$12+COUNTIF(E28:AF28,"OC-E")*CONFIG!$B$9+COUNTIF(E28:AF28,"OC-L")*CONFIG!$B$10+COUNTIF(E28:AF28,"OC-EL")*CONFIG!$B$11+COUNTIF(E28:AF28,"OC-N")*CONFIG!$B$12+COUNTIF(E28:AF28,"ADM")*CONFIG!$B$9+COUNTIF(E28:AF28,"TRN")*CONFIG!$B$9+COUNTIF(E28:AF28,"BH-D")*CONFIG!$B$11+COUNTIF(E28:AF28,"BH-N")*CONFIG!$B$12) -> 84 | AI28: =AH28*AG28 -> 1008 | AJ28: =(COUNTIF(E28:AF28,"OC-E")*CONFIG!$B$9+COUNTIF(E28:AF28,"OC-L")*CONFIG!$B$10+COUNTIF(E28:AF28,"OC-EL")*CONFIG!$B$11+COUNTIF(E28:AF28,"OC-N")*CONFIG!$B$12+COUNTIF(E28:AF28,"OT")*CONFIG!$B$9) -> 0 | AK28: =AJ28*CONFIG!$B$28 -> 0 | AL28: =(COUNTIF(E28:K28,"E")+COUNTIF(E28:K28,"L")+COUNTIF(E28:K28,"OC-E")+COUNTIF(E28:K28,"OC-L"))*6+(COUNTIF(E28:K28,"EL")+COUNTIF(E28:K28,"OC-EL")+COUNTIF(E28:K28,"BH-D"))*12.25+(COUNTIF(E28:K28,"N")+COUNTIF(E28:K28,"OC-N")+COUNTIF(E28:K28,"BH-N"))*12.25 -> 12 | AM28: =(COUNTIF(L28:R28,"E")+COUNTIF(L28:R28,"L")+COUNTIF(L28:R28,"OC-E")+COUNTIF(L28:R28,"OC-L"))*6+(COUNTIF(L28:R28,"EL")+COUNTIF(L28:R28,"OC-EL")+COUNTIF(L28:R28,"BH-D"))*12.25+(COUNTIF(L28:R28,"N")+COUNTIF(L28:R28,"OC-N")+COUNTIF(L28:R28,"BH-N"))*12.25 -> 30 | AN28: =IF(AL28<AM28,"Short W1",IF(AM28<AL28,"Short W2","Balanced")) -> Short W1 | AO28: =(COUNTIF(E28:AF28,"BH-D")*CONFIG!$B$11*AG28*(CONFIG!$B$46-1)+COUNTIF(E28:AF28,"BH-N")*CONFIG!$B$12*AG28*(CONFIG!$B$46-1)) -> 0 | AP28: =AH28/4 -> 21 | AQ28: =IF(AP28>48,"⚠️ >48hr WTR BREACH",IF(AP28>44,"🟡 HIGH","✅ OK")) -> ✅ OK
A52: COVERAGE VALIDATION
A53: Early Count | E53: =COUNTIF(E$4:E$50,"E")+COUNTIF(E$4:E$50,"EL")+COUNTIF(E$4:E$50,"OC-E")+COUNTIF(E$4:E$50,"OC-EL")+COUNTIF(E$4:E$50,"BH-D")+COUNTIF(E$4:E$50,"AG-E") -> 8 | F53: =COUNTIF(F$4:F$50,"E")+COUNTIF(F$4:F$50,"EL")+COUNTIF(F$4:F$50,"OC-E")+COUNTIF(F$4:F$50,"OC-EL")+COUNTIF(F$4:F$50,"BH-D")+COUNTIF(F$4:F$50,"AG-E") -> 8 | G53: =COUNTIF(G$4:G$50,"E")+COUNTIF(G$4:G$50,"EL")+COUNTIF(G$4:G$50,"OC-E")+COUNTIF(G$4:G$50,"OC-EL")+COUNTIF(G$4:G$50,"BH-D")+COUNTIF(G$4:G$50,"AG-E") -> 7 | H53: =COUNTIF(H$4:H$50,"E")+COUNTIF(H$4:H$50,"EL")+COUNTIF(H$4:H$50,"OC-E")+COUNTIF(H$4:H$50,"OC-EL")+COUNTIF(H$4:H$50,"BH-D")+COUNTIF(H$4:H$50,"AG-E") -> 7 | I53: =COUNTIF(I$4:I$50,"E")+COUNTIF(I$4:I$50,"EL")+COUNTIF(I$4:I$50,"OC-E")+COUNTIF(I$4:I$50,"OC-EL")+COUNTIF(I$4:I$50,"BH-D")+COUNTIF(I$4:I$50,"AG-E") -> 8 | J53: =COUNTIF(J$4:J$50,"E")+COUNTIF(J$4:J$50,"EL")+COUNTIF(J$4:J$50,"OC-E")+COUNTIF(J$4:J$50,"OC-EL")+COUNTIF(J$4:J$50,"BH-D")+COUNTIF(J$4:J$50,"AG-E") -> 8 | K53: =COUNTIF(K$4:K$50,"E")+COUNTIF(K$4:K$50,"EL")+COUNTIF(K$4:K$50,"OC-E")+COUNTIF(K$4:K$50,"OC-EL")+COUNTIF(K$4:K$50,"BH-D")+COUNTIF(K$4:K$50,"AG-E") -> 8 | L53: =COUNTIF(L$4:L$50,"E")+COUNTIF(L$4:L$50,"EL")+COUNTIF(L$4:L$50,"OC-E")+COUNTIF(L$4:L$50,"OC-EL")+COUNTIF(L$4:L$50,"BH-D")+COUNTIF(L$4:L$50,"AG-E") -> 7 | ... AF53: =COUNTIF(AF$4:AF$50,"E")+COUNTIF(AF$4:AF$50,"EL")+COUNTIF(AF$4:AF$50,"OC-E")+COUNTIF(AF$4:AF$50,"OC-EL")+COUNTIF(AF$4:AF$50,"BH-D")+COUNTIF(AF$4:AF$50,"AG-E") -> 7
A54: Early Skill ⚡ | E54: =SUMPRODUCT(((E$4:E$50="E")+(E$4:E$50="EL")+(E$4:E$50="OC-E")+(E$4:E$50="OC-EL")+(E$4:E$50="BH-D"))*$D$4:$D$50)+COUNTIF(E$4:E$50,"AG-E")*1 -> 6.5 | F54: =SUMPRODUCT(((F$4:F$50="E")+(F$4:F$50="EL")+(F$4:F$50="OC-E")+(F$4:F$50="OC-EL")+(F$4:F$50="BH-D"))*$D$4:$D$50)+COUNTIF(F$4:F$50,"AG-E")*1 -> 6.5 | G54: =SUMPRODUCT(((G$4:G$50="E")+(G$4:G$50="EL")+(G$4:G$50="OC-E")+(G$4:G$50="OC-EL")+(G$4:G$50="BH-D"))*$D$4:$D$50)+COUNTIF(G$4:G$50,"AG-E")*1 -> 6 | H54: =SUMPRODUCT(((H$4:H$50="E")+(H$4:H$50="EL")+(H$4:H$50="OC-E")+(H$4:H$50="OC-EL")+(H$4:H$50="BH-D"))*$D$4:$D$50)+COUNTIF(H$4:H$50,"AG-E")*1 -> 6 | I54: =SUMPRODUCT(((I$4:I$50="E")+(I$4:I$50="EL")+(I$4:I$50="OC-E")+(I$4:I$50="OC-EL")+(I$4:I$50="BH-D"))*$D$4:$D$50)+COUNTIF(I$4:I$50,"AG-E")*1 -> 6.5 | J54: =SUMPRODUCT(((J$4:J$50="E")+(J$4:J$50="EL")+(J$4:J$50="OC-E")+(J$4:J$50="OC-EL")+(J$4:J$50="BH-D"))*$D$4:$D$50)+COUNTIF(J$4:J$50,"AG-E")*1 -> 6.5 | K54: =SUMPRODUCT(((K$4:K$50="E")+(K$4:K$50="EL")+(K$4:K$50="OC-E")+(K$4:K$50="OC-EL")+(K$4:K$50="BH-D"))*$D$4:$D$50)+COUNTIF(K$4:K$50,"AG-E")*1 -> 6.5 | L54: =SUMPRODUCT(((L$4:L$50="E")+(L$4:L$50="EL")+(L$4:L$50="OC-E")+(L$4:L$50="OC-EL")+(L$4:L$50="BH-D"))*$D$4:$D$50)+COUNTIF(L$4:L$50,"AG-E")*1 -> 6 | ... AF54: =SUMPRODUCT(((AF$4:AF$50="E")+(AF$4:AF$50="EL")+(AF$4:AF$50="OC-E")+(AF$4:AF$50="OC-EL")+(AF$4:AF$50="BH-D"))*$D$4:$D$50)+COUNTIF(AF$4:AF$50,"AG-E")*1 -> 6
A55: Late Count | E55: =COUNTIF(E$4:E$50,"L")+COUNTIF(E$4:E$50,"EL")+COUNTIF(E$4:E$50,"OC-L")+COUNTIF(E$4:E$50,"OC-EL")+COUNTIF(E$4:E$50,"BH-D")+COUNTIF(E$4:E$50,"AG-L") -> 7 | F55: =COUNTIF(F$4:F$50,"L")+COUNTIF(F$4:F$50,"EL")+COUNTIF(F$4:F$50,"OC-L")+COUNTIF(F$4:F$50,"OC-EL")+COUNTIF(F$4:F$50,"BH-D")+COUNTIF(F$4:F$50,"AG-L") -> 7 | G55: =COUNTIF(G$4:G$50,"L")+COUNTIF(G$4:G$50,"EL")+COUNTIF(G$4:G$50,"OC-L")+COUNTIF(G$4:G$50,"OC-EL")+COUNTIF(G$4:G$50,"BH-D")+COUNTIF(G$4:G$50,"AG-L") -> 8 | H55: =COUNTIF(H$4:H$50,"L")+COUNTIF(H$4:H$50,"EL")+COUNTIF(H$4:H$50,"OC-L")+COUNTIF(H$4:H$50,"OC-EL")+COUNTIF(H$4:H$50,"BH-D")+COUNTIF(H$4:H$50,"AG-L") -> 8 | I55: =COUNTIF(I$4:I$50,"L")+COUNTIF(I$4:I$50,"EL")+COUNTIF(I$4:I$50,"OC-L")+COUNTIF(I$4:I$50,"OC-EL")+COUNTIF(I$4:I$50,"BH-D")+COUNTIF(I$4:I$50,"AG-L") -> 7 | J55: =COUNTIF(J$4:J$50,"L")+COUNTIF(J$4:J$50,"EL")+COUNTIF(J$4:J$50,"OC-L")+COUNTIF(J$4:J$50,"OC-EL")+COUNTIF(J$4:J$50,"BH-D")+COUNTIF(J$4:J$50,"AG-L") -> 7 | K55: =COUNTIF(K$4:K$50,"L")+COUNTIF(K$4:K$50,"EL")+COUNTIF(K$4:K$50,"OC-L")+COUNTIF(K$4:K$50,"OC-EL")+COUNTIF(K$4:K$50,"BH-D")+COUNTIF(K$4:K$50,"AG-L") -> 7 | L55: =COUNTIF(L$4:L$50,"L")+COUNTIF(L$4:L$50,"EL")+COUNTIF(L$4:L$50,"OC-L")+COUNTIF(L$4:L$50,"OC-EL")+COUNTIF(L$4:L$50,"BH-D")+COUNTIF(L$4:L$50,"AG-L") -> 8 | ... AF55: =COUNTIF(AF$4:AF$50,"L")+COUNTIF(AF$4:AF$50,"EL")+COUNTIF(AF$4:AF$50,"OC-L")+COUNTIF(AF$4:AF$50,"OC-EL")+COUNTIF(AF$4:AF$50,"BH-D")+COUNTIF(AF$4:AF$50,"AG-L") -> 8
A56: Late Skill ⚡ | E56: =SUMPRODUCT(((E$4:E$50="L")+(E$4:E$50="EL")+(E$4:E$50="OC-L")+(E$4:E$50="OC-EL")+(E$4:E$50="BH-D"))*$D$4:$D$50)+COUNTIF(E$4:E$50,"AG-L")*1 -> 6 | F56: =SUMPRODUCT(((F$4:F$50="L")+(F$4:F$50="EL")+(F$4:F$50="OC-L")+(F$4:F$50="OC-EL")+(F$4:F$50="BH-D"))*$D$4:$D$50)+COUNTIF(F$4:F$50,"AG-L")*1 -> 6 | G56: =SUMPRODUCT(((G$4:G$50="L")+(G$4:G$50="EL")+(G$4:G$50="OC-L")+(G$4:G$50="OC-EL")+(G$4:G$50="BH-D"))*$D$4:$D$50)+COUNTIF(G$4:G$50,"AG-L")*1 -> 7 | H56: =SUMPRODUCT(((H$4:H$50="L")+(H$4:H$50="EL")+(H$4:H$50="OC-L")+(H$4:H$50="OC-EL")+(H$4:H$50="BH-D"))*$D$4:$D$50)+COUNTIF(H$4:H$50,"AG-L")*1 -> 7 | I56: =SUMPRODUCT(((I$4:I$50="L")+(I$4:I$50="EL")+(I$4:I$50="OC-L")+(I$4:I$50="OC-EL")+(I$4:I$50="BH-D"))*$D$4:$D$50)+COUNTIF(I$4:I$50,"AG-L")*1 -> 6 | J56: =SUMPRODUCT(((J$4:J$50="L")+(J$4:J$50="EL")+(J$4:J$50="OC-L")+(J$4:J$50="OC-EL")+(J$4:J$50="BH-D"))*$D$4:$D$50)+COUNTIF(J$4:J$50,"AG-L")*1 -> 6 | K56: =SUMPRODUCT(((K$4:K$50="L")+(K$4:K$50="EL")+(K$4:K$50="OC-L")+(K$4:K$50="OC-EL")+(K$4:K$50="BH-D"))*$D$4:$D$50)+COUNTIF(K$4:K$50,"AG-L")*1 -> 6 | L56: =SUMPRODUCT(((L$4:L$50="L")+(L$4:L$50="EL")+(L$4:L$50="OC-L")+(L$4:L$50="OC-EL")+(L$4:L$50="BH-D"))*$D$4:$D$50)+COUNTIF(L$4:L$50,"AG-L")*1 -> 7 | ... AF56: =SUMPRODUCT(((AF$4:AF$50="L")+(AF$4:AF$50="EL")+(AF$4:AF$50="OC-L")+(AF$4:AF$50="OC-EL")+(AF$4:AF$50="BH-D"))*$D$4:$D$50)+COUNTIF(AF$4:AF$50,"AG-L")*1 -> 7
A57: Night Count | E57: =COUNTIF(E$4:E$50,"N")+COUNTIF(E$4:E$50,"OC-N")+COUNTIF(E$4:E$50,"BH-N")+COUNTIF(E$4:E$50,"AG-N") -> 3 | F57: =COUNTIF(F$4:F$50,"N")+COUNTIF(F$4:F$50,"OC-N")+COUNTIF(F$4:F$50,"BH-N")+COUNTIF(F$4:F$50,"AG-N") -> 3 | G57: =COUNTIF(G$4:G$50,"N")+COUNTIF(G$4:G$50,"OC-N")+COUNTIF(G$4:G$50,"BH-N")+COUNTIF(G$4:G$50,"AG-N") -> 3 | H57: =COUNTIF(H$4:H$50,"N")+COUNTIF(H$4:H$50,"OC-N")+COUNTIF(H$4:H$50,"BH-N")+COUNTIF(H$4:H$50,"AG-N") -> 3 | I57: =COUNTIF(I$4:I$50,"N")+COUNTIF(I$4:I$50,"OC-N")+COUNTIF(I$4:I$50,"BH-N")+COUNTIF(I$4:I$50,"AG-N") -> 3 | J57: =COUNTIF(J$4:J$50,"N")+COUNTIF(J$4:J$50,"OC-N")+COUNTIF(J$4:J$50,"BH-N")+COUNTIF(J$4:J$50,"AG-N") -> 3 | K57: =COUNTIF(K$4:K$50,"N")+COUNTIF(K$4:K$50,"OC-N")+COUNTIF(K$4:K$50,"BH-N")+COUNTIF(K$4:K$50,"AG-N") -> 3 | L57: =COUNTIF(L$4:L$50,"N")+COUNTIF(L$4:L$50,"OC-N")+COUNTIF(L$4:L$50,"BH-N")+COUNTIF(L$4:L$50,"AG-N") -> 3 | ... AF57: =COUNTIF(AF$4:AF$50,"N")+COUNTIF(AF$4:AF$50,"OC-N")+COUNTIF(AF$4:AF$50,"BH-N")+COUNTIF(AF$4:AF$50,"AG-N") -> 3
A58: Night Skill ⚡ | E58: =SUMPRODUCT(((E$4:E$50="N")+(E$4:E$50="OC-N")+(E$4:E$50="BH-N"))*$D$4:$D$50)+COUNTIF(E$4:E$50,"AG-N")*1 -> 2 | F58: =SUMPRODUCT(((F$4:F$50="N")+(F$4:F$50="OC-N")+(F$4:F$50="BH-N"))*$D$4:$D$50)+COUNTIF(F$4:F$50,"AG-N")*1 -> 2 | G58: =SUMPRODUCT(((G$4:G$50="N")+(G$4:G$50="OC-N")+(G$4:G$50="BH-N"))*$D$4:$D$50)+COUNTIF(G$4:G$50,"AG-N")*1 -> 2 | H58: =SUMPRODUCT(((H$4:H$50="N")+(H$4:H$50="OC-N")+(H$4:H$50="BH-N"))*$D$4:$D$50)+COUNTIF(H$4:H$50,"AG-N")*1 -> 2 | I58: =SUMPRODUCT(((I$4:I$50="N")+(I$4:I$50="OC-N")+(I$4:I$50="BH-N"))*$D$4:$D$50)+COUNTIF(I$4:I$50,"AG-N")*1 -> 2 | J58: =SUMPRODUCT(((J$4:J$50="N")+(J$4:J$50="OC-N")+(J$4:J$50="BH-N"))*$D$4:$D$50)+COUNTIF(J$4:J$50,"AG-N")*1 -> 2 | K58: =SUMPRODUCT(((K$4:K$50="N")+(K$4:K$50="OC-N")+(K$4:K$50="BH-N"))*$D$4:$D$50)+COUNTIF(K$4:K$50,"AG-N")*1 -> 2 | L58: =SUMPRODUCT(((L$4:L$50="N")+(L$4:L$50="OC-N")+(L$4:L$50="BH-N"))*$D$4:$D$50)+COUNTIF(L$4:L$50,"AG-N")*1 -> 2 | ... AF58: =SUMPRODUCT(((AF$4:AF$50="N")+(AF$4:AF$50="OC-N")+(AF$4:AF$50="BH-N"))*$D$4:$D$50)+COUNTIF(AF$4:AF$50,"AG-N")*1 -> 2
A59: AL Count | E59: =COUNTIF(E$4:E$50,"AL") -> 0 | F59: =COUNTIF(F$4:F$50,"AL") -> 0 | G59: =COUNTIF(G$4:G$50,"AL") -> 0 | H59: =COUNTIF(H$4:H$50,"AL") -> 0 | I59: =COUNTIF(I$4:I$50,"AL") -> 0 | J59: =COUNTIF(J$4:J$50,"AL") -> 0 | K59: =COUNTIF(K$4:K$50,"AL") -> 0 | L59: =COUNTIF(L$4:L$50,"AL") -> 0 | ... AF59: =COUNTIF(AF$4:AF$50,"AL") -> 0
A60: Sick Count | E60: =COUNTIF(E$4:E$50,"SICK") -> 0 | F60: =COUNTIF(F$4:F$50,"SICK") -> 0 | G60: =COUNTIF(G$4:G$50,"SICK") -> 0 | H60: =COUNTIF(H$4:H$50,"SICK") -> 0 | I60: =COUNTIF(I$4:I$50,"SICK") -> 0 | J60: =COUNTIF(J$4:J$50,"SICK") -> 0 | K60: =COUNTIF(K$4:K$50,"SICK") -> 0 | L60: =COUNTIF(L$4:L$50,"SICK") -> 0 | ... AF60: =COUNTIF(AF$4:AF$50,"SICK") -> 0
A61: Agency Count | E61: =COUNTIF(E$4:E$50,"AG-E")+COUNTIF(E$4:E$50,"AG-L")+COUNTIF(E$4:E$50,"AG-N") -> 0 | F61: =COUNTIF(F$4:F$50,"AG-E")+COUNTIF(F$4:F$50,"AG-L")+COUNTIF(F$4:F$50,"AG-N") -> 0 | G61: =COUNTIF(G$4:G$50,"AG-E")+COUNTIF(G$4:G$50,"AG-L")+COUNTIF(G$4:G$50,"AG-N") -> 0 | H61: =COUNTIF(H$4:H$50,"AG-E")+COUNTIF(H$4:H$50,"AG-L")+COUNTIF(H$4:H$50,"AG-N") -> 0 | I61: =COUNTIF(I$4:I$50,"AG-E")+COUNTIF(I$4:I$50,"AG-L")+COUNTIF(I$4:I$50,"AG-N") -> 0 | J61: =COUNTIF(J$4:J$50,"AG-E")+COUNTIF(J$4:J$50,"AG-L")+COUNTIF(J$4:J$50,"AG-N") -> 0 | K61: =COUNTIF(K$4:K$50,"AG-E")+COUNTIF(K$4:K$50,"AG-L")+COUNTIF(K$4:K$50,"AG-N") -> 0 | L61: =COUNTIF(L$4:L$50,"AG-E")+COUNTIF(L$4:L$50,"AG-L")+COUNTIF(L$4:L$50,"AG-N") -> 0 | ... AF61: =COUNTIF(AF$4:AF$50,"AG-E")+COUNTIF(AF$4:AF$50,"AG-L")+COUNTIF(AF$4:AF$50,"AG-N") -> 0
